Workbook

Sheet JAN
A2: GOVERNO DO ESTADO DO ESPÍRITO SANTO
A3: SUPERINTENDÊNCIA REGIONAL DE EDUCAÇÃO DE CARAPINA
A4: CARTÃO DE PONTO | Q4: 0 | R4: saldo anterior
A6: NOME: | J6: MÊS: | K6: 43830
A7: CARGO: | C7: xxx | J7: CH DIÁRIA: | L7: 0.33333333 | M7: 8:00 às 17:00 | N7: Flexível
A8: FUNÇÃO: | C8: xxx | J8: DIAS ÚTEIS: | L8: =COUNTIF(A14:A43,"U")
A9: EMPRESA: | C9: xxx | J9: CNPJ: | K9: xx | M9: EXERCÍCIO: | N9: 2019 | P9: U: DIA ÚTIL
A10: LOCALIZAÇÃO: | C10: Superintência Regional de Educação de Carapina | J10: NÚMERO FUNCIONAL: | L10: xx | M10: VÍNCULO: | N10: xx | P10: F: SÁBADOS; DOMINGOS E FERIADOS
A11: REGIME JURÍDICO: | C11: Estatutário | F11: ÓRGÃO DE EXERCÍCIO: | I11: Secretaria de Estado da Educação
A12: DIAS DA SEMANA | F12: 1º TURNO | H12: 2º TURNO | J12: 3º TURNO | L12: HORAS TRABALHADAS | M12: CH PADRÃO | N12: SALDO | P12: saldo acumulado até hoje | R12: =SUM(U14:U44)+SUM(FEV!U14:U44)+SUM(MAR!U14:U44)+SUM(ABR!U14:U44)+SUM(MAIO!U14:U44)+SUM(JUN!U14:U44)+SUM(JUL!U14:U44)+SUM(AGO!U14:U44)+SUM(SET!U14:U44)+SUM(OUT!U14:U44)+SUM(NOV!U14:U44)+SUM(DEZ!U14:U44) | U12: =TODAY()
F13: ENTRADA MANHÃ | G13: SAÍDA MANHÃ | H13: ENTRADA TARDE | I13: SAÍDA DA TARDE | J13: ENTRADA EXTRA | K13: SAÍDA EXTRA | L13: POR DIA | M13: DIÁRIA | N13: DIÁRIO
A14: F | B14: =K6 | C14: =WEEKDAY(B14)+1 | F14: 0.33333333 | G14: 0 | H14: 0 | I14: 0 | L14: =IF(A14="U",(G14-F14)+(I14-H14)+(K14-J14),"NÃO ÚTIL") | M14: =IF(A14="U",L7,"NÃO ÚTIL") | N14: =IF(A14="U",(L14-M14),"NÃO ÚTIL") | P14: =IF(N14="não útil",0,N14) | Q14: =P14 | R14: =Q14+$Q$4 | S14: =IF(B14=T14,"HOJE",".") | T14: =TODAY() | U14: =IF(S14="HOJE",R14,0)
A15: =IF(OR(C15=2,C15=8),"F","U") | B15: =B14+1 | C15: =WEEKDAY(B15)+1 | F15: 0 | G15: 0 | H15: 0 | I15: 0 | L15: =IF(A15="U",(G15-F15)+(I15-H15)+(K15-J15),"NÃO ÚTIL") | M15: =IF(A15="U",L7,"NÃO ÚTIL") | N15: =IF(A15="U",(L15-M15),"NÃO ÚTIL") | P15: =IF(N15="não útil",0,N15) | Q15: =P15+Q14 | R15: =Q15+$Q$4 | S15: =IF(B15=T15,"HOJE",".") | T15: =TODAY() | U15: =IF(S15="HOJE",R15,0)
A16: =IF(OR(C16=2,C16=8),"F","U") | B16: =B15+1 | C16: =WEEKDAY(B16)+1 | F16: 0 | G16: 0 | H16: 0 | I16: 0 | L16: =IF(A16="U",(G16-F16)+(I16-H16)+(K16-J16),"NÃO ÚTIL") | M16: =IF(A16="U",L7,"NÃO ÚTIL") | N16: =IF(A16="U",(L16-M16),"NÃO ÚTIL") | P16: =IF(N16="não útil",0,N16) | Q16: =P16+Q15 | R16: =Q16+$Q$4 | S16: =IF(B16=T16,"HOJE",".") | T16: =TODAY() | U16: =IF(S16="HOJE",R16,0)
A17: =IF(OR(C17=2,C17=8),"F","U") | B17: =B16+1 | C17: =WEEKDAY(B17)+1 | F17: 0 | G17: 0 | H17: 0 | I17: 0 | L17: =IF(A17="U",(G17-F17)+(I17-H17)+(K17-J17),"NÃO ÚTIL") | M17: =IF(A17="U",L7,"NÃO ÚTIL") | N17: =IF(A17="U",(L17-M17),"NÃO ÚTIL") | P17: =IF(N17="não útil",0,N17) | Q17: =P17+Q16 | R17: =Q17+$Q$4 | S17: =IF(B17=T17,"HOJE",".") | T17: =TODAY() | U17: =IF(S17="HOJE",R17,0)
A18: =IF(OR(C18=2,C18=8),"F","U") | B18: =B17+1 | C18: =WEEKDAY(B18)+1 | F18: 0 | G18: 0 | H18: 0 | I18: 0 | L18: =IF(A18="U",(G18-F18)+(I18-H18)+(K18-J18),"NÃO ÚTIL") | M18: =IF(A18="U",L7,"NÃO ÚTIL") | N18: =IF(A18="U",(L18-M18),"NÃO ÚTIL") | P18: =IF(N18="não útil",0,N18) | Q18: =P18+Q17 | R18: =Q18+$Q$4 | S18: =IF(B18=T18,"HOJE",".") | T18: =TODAY() | U18: =IF(S18="HOJE",R18,0)
A19: =IF(OR(C19=2,C19=8),"F","U") | B19: =B18+1 | C19: =WEEKDAY(B19)+1 | F19: 0 | G19: 0 | H19: 0 | I19: 0 | L19: =IF(A19="U",(G19-F19)+(I19-H19)+(K19-J19),"NÃO ÚTIL") | M19: =IF(A19="U",L7,"NÃO ÚTIL") | N19: =IF(A19="U",(L19-M19),"NÃO ÚTIL") | P19: =IF(N19="não útil",0,N19) | Q19: =P19+Q18 | R19: =Q19+$Q$4 | S19: =IF(B19=T19,"HOJE",".") | T19: =TODAY() | U19: =IF(S19="HOJE",R19,0)
A20: =IF(OR(C20=2,C20=8),"F","U") | B20: =B19+1 | C20: =WEEKDAY(B20)+1 | F20: 0 | G20: 0 | H20: 0 | I20: 0 | L20: =IF(A20="U",(G20-F20)+(I20-H20)+(K20-J20),"NÃO ÚTIL") | M20: =IF(A20="U",L7,"NÃO ÚTIL") | N20: =IF(A20="U",(L20-M20),"NÃO ÚTIL") | P20: =IF(N20="não útil",0,N20) | Q20: =P20+Q19 | R20: =Q20+$Q$4 | S20: =IF(B20=T20,"HOJE",".") | T20: =TODAY() | U20: =IF(S20="HOJE",R20,0)
A21: =IF(OR(C21=2,C21=8),"F","U") | B21: =B20+1 | C21: =WEEKDAY(B21)+1 | F21: 0 | G21: 0 | H21: 0 | I21: 0 | L21: =IF(A21="U",(G21-F21)+(I21-H21)+(K21-J21),"NÃO ÚTIL") | M21: =IF(A21="U",L7,"NÃO ÚTIL") | N21: =IF(A21="U",(L21-M21),"NÃO ÚTIL") | P21: =IF(N21="não útil",0,N21) | Q21: =P21+Q20 | R21: =Q21+$Q$4 | S21: =IF(B21=T21,"HOJE",".") | T21: =TODAY() | U21: =IF(S21="HOJE",R21,0)
A22: =IF(OR(C22=2,C22=8),"F","U") | B22: =B21+1 | C22: =WEEKDAY(B22)+1 | F22: 0 | G22: 0 | H22: 0 | I22: 0 | L22: =IF(A22="U",(G22-F22)+(I22-H22)+(K22-J22),"NÃO ÚTIL") | M22: =IF(A22="U",L7,"NÃO ÚTIL") | N22: =IF(A22="U",(L22-M22),"NÃO ÚTIL") | P22: =IF(N22="não útil",0,N22) | Q22: =P22+Q21 | R22: =Q22+$Q$4 | S22: =IF(B22=T22,"HOJE",".") | T22: =TODAY() | U22: =IF(S22="HOJE",R22,0)
A23: =IF(OR(C23=2,C23=8),"F","U") | B23: =B22+1 | C23: =WEEKDAY(B23)+1 | F23: 0 | G23: 0 | H23: 0 | I23: 0 | L23: =IF(A23="U",(G23-F23)+(I23-H23)+(K23-J23),"NÃO ÚTIL") | M23: =IF(A23="U",L7,"NÃO ÚTIL") | N23: =IF(A23="U",(L23-M23),"NÃO ÚTIL") | P23: =IF(N23="não útil",0,N23) | Q23: =P23+Q22 | R23: =Q23+$Q$4 | S23: =IF(B23=T23,"HOJE",".") | T23: =TODAY() | U23: =IF(S23="HOJE",R23,0)
A24: =IF(OR(C24=2,C24=8),"F","U") | B24: =B23+1 | C24: =WEEKDAY(B24)+1 | F24: 0 | G24: 0 | H24: 0 | I24: 0 | L24: =IF(A24="U",(G24-F24)+(I24-H24)+(K24-J24),"NÃO ÚTIL") | M24: =IF(A24="U",L7,"NÃO ÚTIL") | N24: =IF(A24="U",(L24-M24),"NÃO ÚTIL") | P24: =IF(N24="não útil",0,N24) | Q24: =P24+Q23 | R24: =Q24+$Q$4 | S24: =IF(B24=T24,"HOJE",".") | T24: =TODAY() | U24: =IF(S24="HOJE",R24,0)
A25: =IF(OR(C25=2,C25=8),"F","U") | B25: =B24+1 | C25: =WEEKDAY(B25)+1 | F25: 0 | G25: 0 | H25: 0 | I25: 0 | L25: =IF(A25="U",(G25-F25)+(I25-H25)+(K25-J25),"NÃO ÚTIL") | M25: =IF(A25="U",L7,"NÃO ÚTIL") | N25: =IF(A25="U",(L25-M25),"NÃO ÚTIL") | P25: =IF(N25="não útil",0,N25) | Q25: =P25+Q24 | R25: =Q25+$Q$4 | S25: =IF(B25=T25,"HOJE",".") | T25: =TODAY() | U25: =IF(S25="HOJE",R25,0)
A26: =IF(OR(C26=2,C26=8),"F","U") | B26: =B25+1 | C26: =WEEKDAY(B26)+1 | F26: 0 | G26: 0 | H26: 0 | I26: 0 | L26: =IF(A26="U",(G26-F26)+(I26-H26)+(K26-J26),"NÃO ÚTIL") | M26: =IF(A26="U",L7,"NÃO ÚTIL") | N26: =IF(A26="U",(L26-M26),"NÃO ÚTIL") | P26: =IF(N26="não útil",0,N26) | Q26: =P26+Q25 | R26: =Q26+$Q$4 | S26: =IF(B26=T26,"HOJE",".") | T26: =TODAY() | U26: =IF(S26="HOJE",R26,0)
A27: =IF(OR(C27=2,C27=8),"F","U") | B27: =B26+1 | C27: =WEEKDAY(B27)+1 | F27: 0 | G27: 0 | H27: 0 | I27: 0 | L27: =IF(A27="U",(G27-F27)+(I27-H27)+(K27-J27),"NÃO ÚTIL") | M27: =IF(A27="U",L7,"NÃO ÚTIL") | N27: =IF(A27="U",(L27-M27),"NÃO ÚTIL") | P27: =IF(N27="não útil",0,N27) | Q27: =P27+Q26 | R27: =Q27+$Q$4 | S27: =IF(B27=T27,"HOJE",".") | T27: =TODAY() | U27: =IF(S27="HOJE",R27,0)
A28: =IF(OR(C28=2,C28=8),"F","U") | B28: =B27+1 | C28: =WEEKDAY(B28)+1 | F28: 0 | G28: 0 | H28: 0 | I28: 0 | L28: =IF(A28="U",(G28-F28)+(I28-H28)+(K28-J28),"NÃO ÚTIL") | M28: =IF(A28="U",L7,"NÃO ÚTIL") | N28: =IF(A28="U",(L28-M28),"NÃO ÚTIL") | P28: =IF(N28="não útil",0,N28) | Q28: =P28+Q27 | R28: =Q28+$Q$4 | S28: =IF(B28=T28,"HOJE",".") | T28: =TODAY() | U28: =IF(S28="HOJE",R28,0)
A29: =IF(OR(C29=2,C29=8),"F","U") | B29: =B28+1 | C29: =WEEKDAY(B29)+1 | F29: 0 | G29: 0 | H29: 0 | I29: 0 | L29: =IF(A29="U",(G29-F29)+(I29-H29)+(K29-J29),"NÃO ÚTIL") | M29: =IF(A29="U",L7,"NÃO ÚTIL") | N29: =IF(A29="U",(L29-M29),"NÃO ÚTIL") | P29: =IF(N29="não útil",0,N29) | Q29: =P29+Q28 | R29: =Q29+$Q$4 | S29: =IF(B29=T29,"HOJE",".") | T29: =TODAY() | U29: =IF(S29="HOJE",R29,0)
A30: =IF(OR(C30=2,C30=8),"F","U") | B30: =B29+1 | C30: =WEEKDAY(B30)+1 | F30: 0 | G30: 0 | H30: 0 | I30: 0 | L30: =IF(A30="U",(G30-F30)+(I30-H30)+(K30-J30),"NÃO ÚTIL") | M30: =IF(A30="U",L7,"NÃO ÚTIL") | N30: =IF(A30="U",(L30-M30),"NÃO ÚTIL") | P30: =IF(N30="não útil",0,N30) | Q30: =P30+Q29 | R30: =Q30+$Q$4 | S30: =IF(B30=T30,"HOJE",".") | T30: =TODAY() | U30: =IF(S30="HOJE",R30,0)
A31: =IF(OR(C31=2,C31=8),"F","U") | B31: =B30+1 | C31: =WEEKDAY(B31)+1 | F31: 0 | G31: 0 | H31: 0 | I31: 0 | L31: =IF(A31="U",(G31-F31)+(I31-H31)+(K31-J31),"NÃO ÚTIL") | M31: =IF(A31="U",L7,"NÃO ÚTIL") | N31: =IF(A31="U",(L31-M31),"NÃO ÚTIL") | P31: =IF(N31="não útil",0,N31) | Q31: =P31+Q30 | R31: =Q31+$Q$4 | S31: =IF(B31=T31,"HOJE",".") | T31: =TODAY() | U31: =IF(S31="HOJE",R31,0)
A32: =IF(OR(C32=2,C32=8),"F","U") | B32: =B31+1 | C32: =WEEKDAY(B32)+1 | F32: 0 | G32: 0 | H32: 0 | I32: 0 | L32: =IF(A32="U",(G32-F32)+(I32-H32)+(K32-J32),"NÃO ÚTIL") | M32: =IF(A32="U",L7,"NÃO ÚTIL") | N32: =IF(A32="U",(L32-M32),"NÃO ÚTIL") | P32: =IF(N32="não útil",0,N32) | Q32: =P32+Q31 | R32: =Q32+$Q$4 | S32: =IF(B32=T32,"HOJE",".") | T32: =TODAY() | U32: =IF(S32="HOJE",R32,0)
A33: =IF(OR(C33=2,C33=8),"F","U") | B33: =B32+1 | C33: =WEEKDAY(B33)+1 | F33: 0 | G33: 0 | H33: 0 | I33: 0 | L33: =IF(A33="U",(G33-F33)+(I33-H33)+(K33-J33),"NÃO ÚTIL") | M33: =IF(A33="U",L7,"NÃO ÚTIL") | N33: =IF(A33="U",(L33-M33),"NÃO ÚTIL") | P33: =IF(N33="não útil",0,N33) | Q33: =P33+Q32 | R33: =Q33+$Q$4 | S33: =IF(B33=T33,"HOJE",".") | T33: =TODAY() | U33: =IF(S33="HOJE",R33,0)
A34: =IF(OR(C34=2,C34=8),"F","U") | B34: =B33+1 | C34: =WEEKDAY(B34)+1 | F34: 0 | G34: 0 | H34: 0 | I34: 0 | L34: =IF(A34="U",(G34-F34)+(I34-H34)+(K34-J34),"NÃO ÚTIL") | M34: =IF(A34="U",L7,"NÃO ÚTIL") | N34: =IF(A34="U",(L34-M34),"NÃO ÚTIL") | P34: =IF(N34="não útil",0,N34) | Q34: =P34+Q33 | R34: =Q34+$Q$4 | S34: =IF(B34=T34,"HOJE",".") | T34: =TODAY() | U34: =IF(S34="HOJE",R34,0)
A35: =IF(OR(C35=2,C35=8),"F","U") | B35: =B34+1 | C35: =WEEKDAY(B35)+1 | F35: 0 | G35: 0 | H35: 0 | I35: 0 | L35: =IF(A35="U",(G35-F35)+(I35-H35)+(K35-J35),"NÃO ÚTIL") | M35: =IF(A35="U",L7,"NÃO ÚTIL") | N35: =IF(A35="U",(L35-M35),"NÃO ÚTIL") | P35: =IF(N35="não útil",0,N35) | Q35: =P35+Q34 | R35: =Q35+$Q$4 | S35: =IF(B35=T35,"HOJE",".") | T35: =TODAY() | U35: =IF(S35="HOJE",R35,0)
A36: =IF(OR(C36=2,C36=8),"F","U") | B36: =B35+1 | C36: =WEEKDAY(B36)+1 | F36: 0 | G36: 0 | H36: 0 | I36: 0 | L36: =IF(A36="U",(G36-F36)+(I36-H36)+(K36-J36),"NÃO ÚTIL") | M36: =IF(A36="U",L7,"NÃO ÚTIL") | N36: =IF(A36="U",(L36-M36),"NÃO ÚTIL") | P36: =IF(N36="não útil",0,N36) | Q36: =P36+Q35 | R36: =Q36+$Q$4 | S36: =IF(B36=T36,"HOJE",".") | T36: =TODAY() | U36: =IF(S36="HOJE",R36,0)
A37: =IF(OR(C37=2,C37=8),"F","U") | B37: =B36+1 | C37: =WEEKDAY(B37)+1 | F37: 0 | G37: 0 | H37: 0 | I37: 0 | L37: =IF(A37="U",(G37-F37)+(I37-H37)+(K37-J37),"NÃO ÚTIL") | M37: =IF(A37="U",L7,"NÃO ÚTIL") | N37: =IF(A37="U",(L37-M37),"NÃO ÚTIL") | P37: =IF(N37="não útil",0,N37) | Q37: =P37+Q36 | R37: =Q37+$Q$4 | S37: =IF(B37=T37,"HOJE",".") | T37: =TODAY() | U37: =IF(S37="HOJE",R37,0)
A38: =IF(OR(C38=2,C38=8),"F","U") | B38: =B37+1 | C38: =WEEKDAY(B38)+1 | F38: 0 | G38: 0 | H38: 0 | I38: 0 | L38: =IF(A38="U",(G38-F38)+(I38-H38)+(K38-J38),"NÃO ÚTIL") | M38: =IF(A38="U",L7,"NÃO ÚTIL") | N38: =IF(A38="U",(L38-M38),"NÃO ÚTIL") | P38: =IF(N38="não útil",0,N38) | Q38: =P38+Q37 | R38: =Q38+$Q$4 | S38: =IF(B38=T38,"HOJE",".") | T38: =TODAY() | U38: =IF(S38="HOJE",R38,0)
A39: =IF(OR(C39=2,C39=8),"F","U") | B39: =B38+1 | C39: =WEEKDAY(B39)+1 | F39: 0 | G39: 0 | H39: 0 | I39: 0 | L39: =IF(A39="U",(G39-F39)+(I39-H39)+(K39-J39),"NÃO ÚTIL") | M39: =IF(A39="U",L7,"NÃO ÚTIL") | N39: =IF(A39="U",(L39-M39),"NÃO ÚTIL") | P39: =IF(N39="não útil",0,N39) | Q39: =P39+Q38 | R39: =Q39+$Q$4 | S39: =IF(B39=T39,"HOJE",".") | T39: =TODAY() | U39: =IF(S39="HOJE",R39,0)
A40: =IF(OR(C40=2,C40=8),"F","U") | B40: =B39+1 | C40: =WEEKDAY(B40)+1 | F40: 0 | G40: 0 | H40: 0 | I40: 0 | L40: =IF(A40="U",(G40-F40)+(I40-H40)+(K40-J40),"NÃO ÚTIL") | M40: =IF(A40="U",L7,"NÃO ÚTIL") | N40: =IF(A40="U",(L40-M40),"NÃO ÚTIL") | P40: =IF(N40="não útil",0,N40) | Q40: =P40+Q39 | R40: =Q40+$Q$4 | S40: =IF(B40=T40,"HOJE",".") | T40: =TODAY() | U40: =IF(S40="HOJE",R40,0)
A41: =IF(OR(C41=2,C41=8),"F","U") | B41: =B40+1 | C41: =WEEKDAY(B41)+1 | F41: 0 | G41: 0 | H41: 0 | I41: 0 | L41: =IF(A41="U",(G41-F41)+(I41-H41)+(K41-J41),"NÃO ÚTIL") | M41: =IF(A41="U",L7,"NÃO ÚTIL") | N41: =IF(A41="U",(L41-M41),"NÃO ÚTIL") | P41: =IF(N41="não útil",0,N41) | Q41: =P41+Q40 | R41: =Q41+$Q$4 | S41: =IF(B41=T41,"HOJE",".") | T41: =TODAY() | U41: =IF(S41="HOJE",R41,0)
A42: =IF(OR(C42=2,C42=8),"F","U") | B42: =B41+1 | C42: =WEEKDAY(B42)+1 | F42: 0 | G42: 0 | H42: 0 | I42: 0 | L42: =IF(A42="U",(G42-F42)+(I42-H42)+(K42-J42),"NÃO ÚTIL") | M42: =IF(A42="U",L7,"NÃO ÚTIL") | N42: =IF(A42="U",(L42-M42),"NÃO ÚTIL") | P42: =IF(N42="não útil",0,N42) | Q42: =P42+Q41 | R42: =Q42+$Q$4 | S42: =IF(B42=T42,"HOJE",".") | T42: =TODAY() | U42: =IF(S42="HOJE",R42,0)
...

Sheet FEV
A2: GOVERNO DO ESTADO DO ESPÍRITO SANTO
A3: SUPERINTENDÊNCIA REGIONAL DE EDUCAÇÃO DE CARAPINA
A4: CARTÃO DE PONTO | Q4: 0 | R4: saldo anterior
A6: NOME: | C6: =JAN!C6:I6 | J6: MÊS: | K6: 43496
A7: CARGO: | C7: =JAN!C7:I7 | J7: CH DIÁRIA: | L7: =JAN!L7 | M7: =JAN!M7 | N7: =JAN!N7
A8: FUNÇÃO: | C8: =JAN!C8:I8 | J8: DIAS ÚTEIS: | L8: =COUNTIF(A14:A41,"U")
A9: EMPRESA: | C9: =JAN!C9:I9 | J9: CNPJ: | K9: =JAN!K9:L9 | M9: EXERCÍCIO: | N9: 2021 | P9: U: DIA ÚTIL
A10: LOCALIZAÇÃO: | C10: =JAN!C10:I10 | J10: NÚMERO FUNCIONAL: | L10: =JAN!L10 | M10: VÍNCULO: | N10: =JAN!N10 | P10: F: SÁBADOS; DOMINGOS E FERIADOS
A11: REGIME JURÍDICO: | C11: =JAN!C11:E11 | F11: ÓRGÃO DE EXERCÍCIO: | I11: Secretaria de Estado da Educação
A12: DIAS DA SEMANA | F12: 1º TURNO | H12: 2º TURNO | J12: 3º TURNO | L12: HORAS TRABALHADAS | M12: CH PADRÃO | N12: SALDO | P12: saldo acumulado até hoje | R12: =SUM(U14:U44)+SUM(FEV!U44)+SUM(MAR!U14:U44)+SUM(ABR!U14:U44)+SUM(MAIO!U14:U44)+SUM(JUN!U14:U44)+SUM(JUL!U14:U44)+SUM(AGO!U14:U44)+SUM(SET!U14:U44)+SUM(OUT!U14:U44)+SUM(NOV!U14:U44)+SUM(DEZ!U14:U44) | U12: =TODAY()
F13: ENTRADA MANHÃ | G13: SAÍDA MANHÃ | H13: ENTRADA TARDE | I13: SAÍDA DA TARDE | J13: ENTRADA EXTRA | K13: SAÍDA EXTRA | L13: POR DIA | M13: DIÁRIA | N13: DIÁRIO
A14: =IF(OR(C14=2,C14=8),"F","U") | B14: =K6 | C14: =WEEKDAY(B14)+1 | F14: 0 | G14: 0 | H14: 0 | I14: 0 | L14: =IF(A14="U",(G14-F14)+(I14-H14)+(K14-J14),"NÃO ÚTIL") | M14: =IF(A14="U",L7,"NÃO ÚTIL") | N14: =IF(A14="U",(L14-M14),"NÃO ÚTIL") | P14: =IF(N14="não útil",0,N14) | Q14: =P14 | R14: =Q14+$Q$4 | S14: =IF(B14=T14,"HOJE",".") | T14: =TODAY() | U14: =IF(S14="HOJE",R14,0)
A15: =IF(OR(C15=2,C15=8),"F","U") | B15: =B14+1 | C15: =WEEKDAY(B15)+1 | F15: 0 | G15: 0 | H15: 0 | I15: 0 | L15: =IF(A15="U",(G15-F15)+(I15-H15)+(K15-J15),"NÃO ÚTIL") | M15: =IF(A15="U",L7,"NÃO ÚTIL") | N15: =IF(A15="U",(L15-M15),"NÃO ÚTIL") | P15: =IF(N15="não útil",0,N15) | Q15: =P15+Q14 | R15: =Q15+$Q$4 | S15: =IF(B15=T15,"HOJE",".") | T15: =TODAY() | U15: =IF(S15="HOJE",R15,0)
A16: =IF(OR(C16=2,C16=8),"F","U") | B16: =B15+1 | C16: =WEEKDAY(B16)+1 | F16: 0 | G16: 0 | H16: 0 | I16: 0 | L16: =IF(A16="U",(G16-F16)+(I16-H16)+(K16-J16),"NÃO ÚTIL") | M16: =IF(A16="U",L7,"NÃO ÚTIL") | N16: =IF(A16="U",(L16-M16),"NÃO ÚTIL") | P16: =IF(N16="não útil",0,N16) | Q16: =P16+Q15 | R16: =Q16+$Q$4 | S16: =IF(B16=T16,"HOJE",".") | T16: =TODAY() | U16: =IF(S16="HOJE",R16,0)
A17: =IF(OR(C17=2,C17=8),"F","U") | B17: =B16+1 | C17: =WEEKDAY(B17)+1 | F17: 0 | G17: 0 | H17: 0 | I17: 0 | L17: =IF(A17="U",(G17-F17)+(I17-H17)+(K17-J17),"NÃO ÚTIL") | M17: =IF(A17="U",L7,"NÃO ÚTIL") | N17: =IF(A17="U",(L17-M17),"NÃO ÚTIL") | P17: =IF(N17="não útil",0,N17) | Q17: =P17+Q16 | R17: =Q17+$Q$4 | S17: =IF(B17=T17,"HOJE",".") | T17: =TODAY() | U17: =IF(S17="HOJE",R17,0)
A18: =IF(OR(C18=2,C18=8),"F","U") | B18: =B17+1 | C18: =WEEKDAY(B18)+1 | F18: 0 | G18: 0 | H18: 0 | I18: 0 | L18: =IF(A18="U",(G18-F18)+(I18-H18)+(K18-J18),"NÃO ÚTIL") | M18: =IF(A18="U",L7,"NÃO ÚTIL") | N18: =IF(A18="U",(L18-M18),"NÃO ÚTIL") | P18: =IF(N18="não útil",0,N18) | Q18: =P18+Q17 | R18: =Q18+$Q$4 | S18: =IF(B18=T18,"HOJE",".") | T18: =TODAY() | U18: =IF(S18="HOJE",R18,0)
A19: =IF(OR(C19=2,C19=8),"F","U") | B19: =B18+1 | C19: =WEEKDAY(B19)+1 | F19: 0 | G19: 0 | H19: 0 | I19: 0 | L19: =IF(A19="U",(G19-F19)+(I19-H19)+(K19-J19),"NÃO ÚTIL") | M19: =IF(A19="U",L7,"NÃO ÚTIL") | N19: =IF(A19="U",(L19-M19),"NÃO ÚTIL") | P19: =IF(N19="não útil",0,N19) | Q19: =P19+Q18 | R19: =Q19+$Q$4 | S19: =IF(B19=T19,"HOJE",".") | T19: =TODAY() | U19: =IF(S19="HOJE",R19,0)
A20: =IF(OR(C20=2,C20=8),"F","U") | B20: =B19+1 | C20: =WEEKDAY(B20)+1 | F20: 0 | G20: 0 | H20: 0 | I20: 0 | L20: =IF(A20="U",(G20-F20)+(I20-H20)+(K20-J20),"NÃO ÚTIL") | M20: 0.33333333 | N20: =IF(A20="U",(L20-M20),"NÃO ÚTIL") | P20: =IF(N20="não útil",0,N20) | Q20: =P20+Q19 | R20: =Q20+$Q$4 | S20: =IF(B20=T20,"HOJE",".") | T20: =TODAY() | U20: =IF(S20="HOJE",R20,0)
A21: =IF(OR(C21=2,C21=8),"F","U") | B21: =B20+1 | C21: =WEEKDAY(B21)+1 | F21: 0 | G21: 0 | H21: 0 | I21: 0 | L21: =IF(A21="U",(G21-F21)+(I21-H21)+(K21-J21),"NÃO ÚTIL") | M21: =IF(A21="U",L7,"NÃO ÚTIL") | N21: =IF(A21="U",(L21-M21),"NÃO ÚTIL") | P21: =IF(N21="não útil",0,N21) | Q21: =P21+Q20 | R21: =Q21+$Q$4 | S21: =IF(B21=T21,"HOJE",".") | T21: =TODAY() | U21: =IF(S21="HOJE",R21,0)
A22: =IF(OR(C22=2,C22=8),"F","U") | B22: =B21+1 | C22: =WEEKDAY(B22)+1 | F22: 0 | G22: 0 | H22: 0 | I22: 0 | L22: =IF(A22="U",(G22-F22)+(I22-H22)+(K22-J22),"NÃO ÚTIL") | M22: =IF(A22="U",L7,"NÃO ÚTIL") | N22: =IF(A22="U",(L22-M22),"NÃO ÚTIL") | P22: =IF(N22="não útil",0,N22) | Q22: =P22+Q21 | R22: =Q22+$Q$4 | S22: =IF(B22=T22,"HOJE",".") | T22: =TODAY() | U22: =IF(S22="HOJE",R22,0)
A23: =IF(OR(C23=2,C23=8),"F","U") | B23: =B22+1 | C23: =WEEKDAY(B23)+1 | F23: 0 | G23: 0 | H23: 0 | I23: 0 | L23: =IF(A23="U",(G23-F23)+(I23-H23)+(K23-J23),"NÃO ÚTIL") | M23: =IF(A23="U",L7,"NÃO ÚTIL") | N23: =IF(A23="U",(L23-M23),"NÃO ÚTIL") | P23: =IF(N23="não útil",0,N23) | Q23: =P23+Q22 | R23: =Q23+$Q$4 | S23: =IF(B23=T23,"HOJE",".") | T23: =TODAY() | U23: =IF(S23="HOJE",R23,0)
A24: =IF(OR(C24=2,C24=8),"F","U") | B24: =B23+1 | C24: =WEEKDAY(B24)+1 | F24: 0 | G24: 0 | H24: 0 | I24: 0 | L24: =IF(A24="U",(G24-F24)+(I24-H24)+(K24-J24),"NÃO ÚTIL") | M24: =IF(A24="U",L7,"NÃO ÚTIL") | N24: =IF(A24="U",(L24-M24),"NÃO ÚTIL") | P24: =IF(N24="não útil",0,N24) | Q24: =P24+Q23 | R24: =Q24+$Q$4 | S24: =IF(B24=T24,"HOJE",".") | T24: =TODAY() | U24: =IF(S24="HOJE",R24,0)
A25: =IF(OR(C25=2,C25=8),"F","U") | B25: =B24+1 | C25: =WEEKDAY(B25)+1 | F25: 0 | G25: 0 | H25: 0 | I25: 0 | L25: =IF(A25="U",(G25-F25)+(I25-H25)+(K25-J25),"NÃO ÚTIL") | M25: =IF(A25="U",L7,"NÃO ÚTIL") | N25: =IF(A25="U",(L25-M25),"NÃO ÚTIL") | P25: =IF(N25="não útil",0,N25) | Q25: =P25+Q24 | R25: =Q25+$Q$4 | S25: =IF(B25=T25,"HOJE",".") | T25: =TODAY() | U25: =IF(S25="HOJE",R25,0)
A26: =IF(OR(C26=2,C26=8),"F","U") | B26: =B25+1 | C26: =WEEKDAY(B26)+1 | F26: 0 | G26: 0 | H26: 0 | I26: 0 | L26: =IF(A26="U",(G26-F26)+(I26-H26)+(K26-J26),"NÃO ÚTIL") | M26: =IF(A26="U",L7,"NÃO ÚTIL") | N26: =IF(A26="U",(L26-M26),"NÃO ÚTIL") | P26: =IF(N26="não útil",0,N26) | Q26: =P26+Q25 | R26: =Q26+$Q$4 | S26: =IF(B26=T26,"HOJE",".") | T26: =TODAY() | U26: =IF(S26="HOJE",R26,0)
A27: =IF(OR(C27=2,C27=8),"F","U") | B27: =B26+1 | C27: =WEEKDAY(B27)+1 | F27: 0 | G27: 0 | H27: 0 | I27: 0 | L27: =IF(A27="U",(G27-F27)+(I27-H27)+(K27-J27),"NÃO ÚTIL") | M27: 0.33333333 | N27: =IF(A27="U",(L27-M27),"NÃO ÚTIL") | P27: =IF(N27="não útil",0,N27) | Q27: =P27+Q26 | R27: =Q27+$Q$4 | S27: =IF(B27=T27,"HOJE",".") | T27: =TODAY() | U27: =IF(S27="HOJE",R27,0)
A28: =IF(OR(C28=2,C28=8),"F","U") | B28: =B27+1 | C28: =WEEKDAY(B28)+1 | F28: 0 | G28: 0 | H28: 0 | I28: 0 | L28: =IF(A28="U",(G28-F28)+(I28-H28)+(K28-J28),"NÃO ÚTIL") | M28: =IF(A28="U",L7,"NÃO ÚTIL") | N28: =IF(A28="U",(L28-M28),"NÃO ÚTIL") | P28: =IF(N28="não útil",0,N28) | Q28: =P28+Q27 | R28: =Q28+$Q$4 | S28: =IF(B28=T28,"HOJE",".") | T28: =TODAY() | U28: =IF(S28="HOJE",R28,0)
A29: =IF(OR(C29=2,C29=8),"F","U") | B29: =B28+1 | C29: =WEEKDAY(B29)+1 | F29: 0 | G29: 0 | H29: 0 | I29: 0 | L29: =IF(A29="U",(G29-F29)+(I29-H29)+(K29-J29),"NÃO ÚTIL") | M29: =IF(A29="U",L7,"NÃO ÚTIL") | N29: =IF(A29="U",(L29-M29),"NÃO ÚTIL") | P29: =IF(N29="não útil",0,N29) | Q29: =P29+Q28 | R29: =Q29+$Q$4 | S29: =IF(B29=T29,"HOJE",".") | T29: =TODAY() | U29: =IF(S29="HOJE",R29,0)
A30: =IF(OR(C30=2,C30=8),"F","U") | B30: =B29+1 | C30: =WEEKDAY(B30)+1 | F30: 0 | G30: 0 | H30: 0 | I30: 0 | L30: =IF(A30="U",(G30-F30)+(I30-H30)+(K30-J30),"NÃO ÚTIL") | M30: =IF(A30="U",L7,"NÃO ÚTIL") | N30: =IF(A30="U",(L30-M30),"NÃO ÚTIL") | P30: =IF(N30="não útil",0,N30) | Q30: =P30+Q29 | R30: =Q30+$Q$4 | S30: =IF(B30=T30,"HOJE",".") | T30: =TODAY() | U30: =IF(S30="HOJE",R30,0)
A31: =IF(OR(C31=2,C31=8),"F","U") | B31: =B30+1 | C31: =WEEKDAY(B31)+1 | F31: 0 | G31: 0 | H31: 0 | I31: 0 | L31: =IF(A31="U",(G31-F31)+(I31-H31)+(K31-J31),"NÃO ÚTIL") | M31: =IF(A31="U",L7,"NÃO ÚTIL") | N31: =IF(A31="U",(L31-M31),"NÃO ÚTIL") | P31: =IF(N31="não útil",0,N31) | Q31: =P31+Q30 | R31: =Q31+$Q$4 | S31: =IF(B31=T31,"HOJE",".") | T31: =TODAY() | U31: =IF(S31="HOJE",R31,0)
A32: =IF(OR(C32=2,C32=8),"F","U") | B32: =B31+1 | C32: =WEEKDAY(B32)+1 | F32: 0 | G32: 0 | H32: 0 | I32: 0 | L32: =IF(A32="U",(G32-F32)+(I32-H32)+(K32-J32),"NÃO ÚTIL") | M32: =IF(A32="U",L7,"NÃO ÚTIL") | N32: =IF(A32="U",(L32-M32),"NÃO ÚTIL") | P32: =IF(N32="não útil",0,N32) | Q32: =P32+Q31 | R32: =Q32+$Q$4 | S32: =IF(B32=T32,"HOJE",".") | T32: =TODAY() | U32: =IF(S32="HOJE",R32,0)
A33: =IF(OR(C33=2,C33=8),"F","U") | B33: =B32+1 | C33: =WEEKDAY(B33)+1 | F33: 0 | G33: 0 | H33: 0 | I33: 0 | L33: =IF(A33="U",(G33-F33)+(I33-H33)+(K33-J33),"NÃO ÚTIL") | M33: =IF(A33="U",L7,"NÃO ÚTIL") | N33: =IF(A33="U",(L33-M33),"NÃO ÚTIL") | P33: =IF(N33="não útil",0,N33) | Q33: =P33+Q32 | R33: =Q33+$Q$4 | S33: =IF(B33=T33,"HOJE",".") | T33: =TODAY() | U33: =IF(S33="HOJE",R33,0)
A34: =IF(OR(C34=2,C34=8),"F","U") | B34: =B33+1 | C34: =WEEKDAY(B34)+1 | F34: 0 | G34: 0 | H34: 0 | I34: 0 | L34: =IF(A34="U",(G34-F34)+(I34-H34)+(K34-J34),"NÃO ÚTIL") | M34: =IF(A34="U",L7,"NÃO ÚTIL") | N34: =IF(A34="U",(L34-M34),"NÃO ÚTIL") | P34: =IF(N34="não útil",0,N34) | Q34: =P34+Q33 | R34: =Q34+$Q$4 | S34: =IF(B34=T34,"HOJE",".") | T34: =TODAY() | U34: =IF(S34="HOJE",R34,0)
A35: =IF(OR(C35=2,C35=8),"F","U") | B35: =B34+1 | C35: =WEEKDAY(B35)+1 | F35: 0 | G35: 0 | H35: 0 | I35: 0 | L35: =IF(A35="U",(G35-F35)+(I35-H35)+(K35-J35),"NÃO ÚTIL") | M35: =IF(A35="U",L7,"NÃO ÚTIL") | N35: =IF(A35="U",(L35-M35),"NÃO ÚTIL") | P35: =IF(N35="não útil",0,N35) | Q35: =P35+Q34 | R35: =Q35+$Q$4 | S35: =IF(B35=T35,"HOJE",".") | T35: =TODAY() | U35: =IF(S35="HOJE",R35,0)
A36: =IF(OR(C36=2,C36=8),"F","U") | B36: =B35+1 | C36: =WEEKDAY(B36)+1 | F36: 0 | G36: 0 | H36: 0 | I36: 0 | L36: =IF(A36="U",(G36-F36)+(I36-H36)+(K36-J36),"NÃO ÚTIL") | M36: =IF(A36="U",L7,"NÃO ÚTIL") | N36: =IF(A36="U",(L36-M36),"NÃO ÚTIL") | P36: =IF(N36="não útil",0,N36) | Q36: =P36+Q35 | R36: =Q36+$Q$4 | S36: =IF(B36=T36,"HOJE",".") | T36: =TODAY() | U36: =IF(S36="HOJE",R36,0)
A37: =IF(OR(C37=2,C37=8),"F","U") | B37: =B36+1 | C37: =WEEKDAY(B37)+1 | F37: 0 | G37: 0 | H37: 0 | I37: 0 | L37: =IF(A37="U",(G37-F37)+(I37-H37)+(K37-J37),"NÃO ÚTIL") | M37: =IF(A37="U",L7,"NÃO ÚTIL") | N37: =IF(A37="U",(L37-M37),"NÃO ÚTIL") | P37: =IF(N37="não útil",0,N37) | Q37: =P37+Q36 | R37: =Q37+$Q$4 | S37: =IF(B37=T37,"HOJE",".") | T37: =TODAY() | U37: =IF(S37="HOJE",R37,0)
A38: =IF(OR(C38=2,C38=8),"F","U") | B38: =B37+1 | C38: =WEEKDAY(B38)+1 | F38: 0 | G38: 0 | H38: 0 | I38: 0 | L38: =IF(A38="U",(G38-F38)+(I38-H38)+(K38-J38),"NÃO ÚTIL") | M38: =IF(A38="U",L7,"NÃO ÚTIL") | N38: =IF(A38="U",(L38-M38),"NÃO ÚTIL") | P38: =IF(N38="não útil",0,N38) | Q38: =P38+Q37 | R38: =Q38+$Q$4 | S38: =IF(B38=T38,"HOJE",".") | T38: =TODAY() | U38: =IF(S38="HOJE",R38,0)
A39: =IF(OR(C39=2,C39=8),"F","U") | B39: =B38+1 | C39: =WEEKDAY(B39)+1 | F39: 0 | G39: 0 | H39: 0 | I39: 0 | L39: =IF(A39="U",(G39-F39)+(I39-H39)+(K39-J39),"NÃO ÚTIL") | M39: =IF(A39="U",L7,"NÃO ÚTIL") | N39: =IF(A39="U",(L39-M39),"NÃO ÚTIL") | P39: =IF(N39="não útil",0,N39) | Q39: =P39+Q38 | R39: =Q39+$Q$4 | S39: =IF(B39=T39,"HOJE",".") | T39: =TODAY() | U39: =IF(S39="HOJE",R39,0)
A40: =IF(OR(C40=2,C40=8),"F","U") | B40: =B39+1 | C40: =WEEKDAY(B40)+1 | F40: 0 | G40: 0 | H40: 0 | I40: 0 | L40: =IF(A40="U",(G40-F40)+(I40-H40)+(K40-J40),"NÃO ÚTIL") | M40: =IF(A40="U",L7,"NÃO ÚTIL") | N40: =IF(A40="U",(L40-M40),"NÃO ÚTIL") | P40: =IF(N40="não útil",0,N40) | Q40: =P40+Q39 | R40: =Q40+$Q$4 | S40: =IF(B40=T40,"HOJE",".") | T40: =TODAY() | U40: =IF(S40="HOJE",R40,0)
A41: =IF(OR(C41=2,C41=8),"F","U") | B41: =B40+1 | C41: =WEEKDAY(B41)+1 | F41: 0 | G41: 0 | H41: 0 | I41: 0 | L41: =IF(A41="U",(G41-F41)+(I41-H41)+(K41-J41),"NÃO ÚTIL") | M41: =IF(A41="U",L7,"NÃO ÚTIL") | N41: =IF(A41="U",(L41-M41),"NÃO ÚTIL") | P41: =IF(N41="não útil",0,N41) | Q41: =P41+Q40 | R41: =Q41+$Q$4 | S41: =IF(B41=T41,"HOJE",".") | T41: =TODAY() | U41: =IF(S41="HOJE",R41,0)
A42: =IF(OR(C42=2,C42=8),"F","U") | B42: =B41+1 | C42: =WEEKDAY(B42)+1 | F42: 0 | G42: 0 | H42: 0 | I42: 0 | L42: =IF(A42="U",(G42-F42)+(I42-H42)+(K42-J42),"NÃO ÚTIL") | M42: =IF(A42="U",L7,"NÃO ÚTIL") | N42: =IF(A42="U",(L42-M42),"NÃO ÚTIL") | P42: =IF(N42="não útil",0,N42) | Q42: =P42+Q41 | R42: =Q42+$Q$4 | S42: =IF(B42=T42,"HOJE",".") | T42: =TODAY() | U42: =IF(S42="HOJE",R42,0)
...

Sheet MAR
A2: GOVERNO DO ESTADO DO ESPÍRITO SANTO
A3: SUPERINTENDÊNCIA REGIONAL DE EDUCAÇÃO DE CARAPINA
A4: CARTÃO DE PONTO | Q4: 0 | R4: saldo anterior
A6: NOME: | C6: =JAN!C6:I6 | J6: MÊS: | K6: 43524
A7: CARGO: | C7: =JAN!C7:I7 | J7: CH DIÁRIA: | L7: =JAN!L7 | M7: =JAN!M7 | N7: =JAN!N7
A8: FUNÇÃO: | C8: =JAN!C8:I8 | J8: DIAS ÚTEIS: | L8: =COUNTIF(A14:A43,"U")
A9: EMPRESA: | C9: =JAN!C9:I9 | J9: CNPJ: | K9: =JAN!K9:L9 | M9: EXERCÍCIO: | N9: 2021 | P9: U: DIA ÚTIL
A10: LOCALIZAÇÃO: | C10: =JAN!C10:I10 | J10: NÚMERO FUNCIONAL: | L10: =JAN!L10 | M10: VÍNCULO: | N10: =JAN!N10 | P10: F: SÁBADOS; DOMINGOS E FERIADOS
A11: REGIME JURÍDICO: | C11: =JAN!C11:E11 | F11: ÓRGÃO DE EXERCÍCIO: | I11: Secretaria de Estado da Educação
A12: DIAS DA SEMANA | F12: 1º TURNO | H12: 2º TURNO | J12: 3º TURNO | L12: HORAS TRABALHADAS | M12: CH PADRÃO | N12: SALDO | P12: saldo acumulado até hoje | R12: =SUM(U14:U44)+SUM(FEV!U44)+SUM(MAR!U14:U44)+SUM(ABR!U14:U44)+SUM(MAIO!U14:U44)+SUM(JUN!U14:U44)+SUM(JUL!U14:U44)+SUM(AGO!U14:U44)+SUM(SET!U14:U44)+SUM(OUT!U14:U44)+SUM(NOV!U14:U44)+SUM(DEZ!U14:U44) | U12: =TODAY()
F13: ENTRADA MANHÃ | G13: SAÍDA MANHÃ | H13: ENTRADA TARDE | I13: SAÍDA DA TARDE | J13: ENTRADA EXTRA | K13: SAÍDA EXTRA | L13: POR DIA | M13: DIÁRIA | N13: DIÁRIO
A14: F | B14: =K6 | C14: =WEEKDAY(B14)+1 | F14: 0 | G14: 0 | H14: 0 | I14: 0 | L14: =IF(A14="U",(G14-F14)+(I14-H14)+(K14-J14),"NÃO ÚTIL") | M14: =IF(A14="U",L7,"NÃO ÚTIL") | N14: 0 | P14: =IF(N14="não útil",0,N14) | Q14: =P14 | R14: =Q14+$Q$4 | S14: =IF(B14=T14,"HOJE",".") | T14: =TODAY() | U14: =IF(S14="HOJE",R14,0)
A15: F | B15: =B14+1 | C15: =WEEKDAY(B15)+1 | F15: 0 | G15: 0 | H15: 0 | I15: 0 | L15: =IF(A15="U",(G15-F15)+(I15-H15)+(K15-J15),"NÃO ÚTIL") | M15: =IF(A15="U",L7,"NÃO ÚTIL") | N15: =IF(A15="U",(L15-M15),"NÃO ÚTIL") | P15: =IF(N15="não útil",0,N15) | Q15: =P15+Q14 | R15: =Q15+$Q$4 | S15: =IF(B15=T15,"HOJE",".") | T15: =TODAY() | U15: =IF(S15="HOJE",R15,0)
A16: =IF(OR(C16=2,C16=8),"F","U") | B16: =B15+1 | C16: =WEEKDAY(B16)+1 | F16: 0 | G16: 0 | H16: 0 | I16: 0 | L16: =IF(A16="U",(G16-F16)+(I16-H16)+(K16-J16),"NÃO ÚTIL") | M16: =IF(A16="U",L7,"NÃO ÚTIL") | N16: =IF(A16="U",(L16-M16),"NÃO ÚTIL") | P16: =IF(N16="não útil",0,N16) | Q16: =P16+Q15 | R16: =Q16+$Q$4 | S16: =IF(B16=T16,"HOJE",".") | T16: =TODAY() | U16: =IF(S16="HOJE",R16,0)
A17: U | B17: =B16+1 | C17: =WEEKDAY(B17)+1 | F17: 0 | G17: 0 | H17: 0 | I17: 0 | L17: =IF(A17="U",(G17-F17)+(I17-H17)+(K17-J17),"NÃO ÚTIL") | M17: =IF(A17="U",L7,"NÃO ÚTIL") | N17: =IF(A17="U",(L17-M17),"NÃO ÚTIL") | P17: =IF(N17="não útil",0,N17) | Q17: =P17+Q16 | R17: =Q17+$Q$4 | S17: =IF(B17=T17,"HOJE",".") | T17: =TODAY() | U17: =IF(S17="HOJE",R17,0)
A18: F | B18: =B17+1 | C18: =WEEKDAY(B18)+1 | F18: 0 | G18: 0 | H18: 0 | I18: 0 | L18: =IF(A18="U",(G18-F18)+(I18-H18)+(K18-J18),"NÃO ÚTIL") | M18: =IF(A18="U",L7,"NÃO ÚTIL") | N18: =IF(A18="U",(L18-M18),"NÃO ÚTIL") | P18: =IF(N18="não útil",0,N18) | Q18: =P18+Q17 | R18: =Q18+$Q$4 | S18: =IF(B18=T18,"HOJE",".") | T18: =TODAY() | U18: =IF(S18="HOJE",R18,0)
A19: F | B19: =B18+1 | C19: =WEEKDAY(B19)+1 | F19: 0 | G19: 0 | H19: 0 | I19: 0 | L19: =IF(A19="U",(G19-F19)+(I19-H19)+(K19-J19),"NÃO ÚTIL") | M19: =IF(A19="U",L7,"NÃO ÚTIL") | N19: =IF(A19="U",(L19-M19),"NÃO ÚTIL") | P19: =IF(N19="não útil",0,N19) | Q19: =P19+Q18 | R19: =Q19+$Q$4 | S19: =IF(B19=T19,"HOJE",".") | T19: =TODAY() | U19: =IF(S19="HOJE",R19,0)
A20: =IF(OR(C20=2,C20=8),"F","U") | B20: =B19+1 | C20: =WEEKDAY(B20)+1 | F20: 0 | G20: 0 | H20: 0 | I20: 0 | L20: =IF(A20="U",(G20-F20)+(I20-H20)+(K20-J20),"NÃO ÚTIL") | M20: =IF(A20="U",L7,"NÃO ÚTIL") | N20: =IF(A20="U",(L20-M20),"NÃO ÚTIL") | P20: =IF(N20="não útil",0,N20) | Q20: =P20+Q19 | R20: =Q20+$Q$4 | S20: =IF(B20=T20,"HOJE",".") | T20: =TODAY() | U20: =IF(S20="HOJE",R20,0)
A21: =IF(OR(C21=2,C21=8),"F","U") | B21: =B20+1 | C21: =WEEKDAY(B21)+1 | F21: 0 | G21: 0 | H21: 0 | I21: 0 | L21: =IF(A21="U",(G21-F21)+(I21-H21)+(K21-J21),"NÃO ÚTIL") | M21: =IF(A21="U",L7,"NÃO ÚTIL") | N21: =IF(A21="U",(L21-M21),"NÃO ÚTIL") | P21: =IF(N21="não útil",0,N21) | Q21: =P21+Q20 | R21: =Q21+$Q$4 | S21: =IF(B21=T21,"HOJE",".") | T21: =TODAY() | U21: =IF(S21="HOJE",R21,0)
A22: =IF(OR(C22=2,C22=8),"F","U") | B22: =B21+1 | C22: =WEEKDAY(B22)+1 | F22: 0 | G22: 0 | H22: 0 | I22: 0 | L22: =IF(A22="U",(G22-F22)+(I22-H22)+(K22-J22),"NÃO ÚTIL") | M22: =IF(A22="U",L7,"NÃO ÚTIL") | N22: =IF(A22="U",(L22-M22),"NÃO ÚTIL") | P22: =IF(N22="não útil",0,N22) | Q22: =P22+Q21 | R22: =Q22+$Q$4 | S22: =IF(B22=T22,"HOJE",".") | T22: =TODAY() | U22: =IF(S22="HOJE",R22,0)
A23: =IF(OR(C23=2,C23=8),"F","U") | B23: =B22+1 | C23: =WEEKDAY(B23)+1 | F23: 0 | G23: 0 | H23: 0 | I23: 0 | L23: =IF(A23="U",(G23-F23)+(I23-H23)+(K23-J23),"NÃO ÚTIL") | M23: =IF(A23="U",L7,"NÃO ÚTIL") | N23: =IF(A23="U",(L23-M23),"NÃO ÚTIL") | P23: =IF(N23="não útil",0,N23) | Q23: =P23+Q22 | R23: =Q23+$Q$4 | S23: =IF(B23=T23,"HOJE",".") | T23: =TODAY() | U23: =IF(S23="HOJE",R23,0)
A24: =IF(OR(C24=2,C24=8),"F","U") | B24: =B23+1 | C24: =WEEKDAY(B24)+1 | F24: 0 | G24: 0 | H24: 0 | I24: 0 | L24: =IF(A24="U",(G24-F24)+(I24-H24)+(K24-J24),"NÃO ÚTIL") | M24: =IF(A24="U",L7,"NÃO ÚTIL") | N24: =IF(A24="U",(L24-M24),"NÃO ÚTIL") | P24: =IF(N24="não útil",0,N24) | Q24: =P24+Q23 | R24: =Q24+$Q$4 | S24: =IF(B24=T24,"HOJE",".") | T24: =TODAY() | U24: =IF(S24="HOJE",R24,0)
A25: =IF(OR(C25=2,C25=8),"F","U") | B25: =B24+1 | C25: =WEEKDAY(B25)+1 | F25: 0 | G25: 0 | H25: 0 | I25: 0 | L25: =IF(A25="U",(G25-F25)+(I25-H25)+(K25-J25),"NÃO ÚTIL") | M25: =IF(A25="U",L7,"NÃO ÚTIL") | N25: =IF(A25="U",(L25-M25),"NÃO ÚTIL") | P25: =IF(N25="não útil",0,N25) | Q25: =P25+Q24 | R25: =Q25+$Q$4 | S25: =IF(B25=T25,"HOJE",".") | T25: =TODAY() | U25: =IF(S25="HOJE",R25,0)
A26: =IF(OR(C26=2,C26=8),"F","U") | B26: =B25+1 | C26: =WEEKDAY(B26)+1 | F26: 0 | G26: 0 | H26: 0 | I26: 0 | L26: =IF(A26="U",(G26-F26)+(I26-H26)+(K26-J26),"NÃO ÚTIL") | M26: =IF(A26="U",L7,"NÃO ÚTIL") | N26: =IF(A26="U",(L26-M26),"NÃO ÚTIL") | P26: =IF(N26="não útil",0,N26) | Q26: =P26+Q25 | R26: =Q26+$Q$4 | S26: =IF(B26=T26,"HOJE",".") | T26: =TODAY() | U26: =IF(S26="HOJE",R26,0)
A27: =IF(OR(C27=2,C27=8),"F","U") | B27: =B26+1 | C27: =WEEKDAY(B27)+1 | F27: 0 | G27: 0 | H27: 0 | I27: 0 | L27: =IF(A27="U",(G27-F27)+(I27-H27)+(K27-J27),"NÃO ÚTIL") | M27: =IF(A27="U",L7,"NÃO ÚTIL") | N27: =IF(A27="U",(L27-M27),"NÃO ÚTIL") | P27: =IF(N27="não útil",0,N27) | Q27: =P27+Q26 | R27: =Q27+$Q$4 | S27: =IF(B27=T27,"HOJE",".") | T27: =TODAY() | U27: =IF(S27="HOJE",R27,0)
A28: =IF(OR(C28=2,C28=8),"F","U") | B28: =B27+1 | C28: =WEEKDAY(B28)+1 | F28: 0 | G28: 0 | H28: 0 | I28: 0 | L28: =IF(A28="U",(G28-F28)+(I28-H28)+(K28-J28),"NÃO ÚTIL") | M28: =IF(A28="U",L7,"NÃO ÚTIL") | N28: =IF(A28="U",(L28-M28),"NÃO ÚTIL") | P28: =IF(N28="não útil",0,N28) | Q28: =P28+Q27 | R28: =Q28+$Q$4 | S28: =IF(B28=T28,"HOJE",".") | T28: =TODAY() | U28: =IF(S28="HOJE",R28,0)
A29: =IF(OR(C29=2,C29=8),"F","U") | B29: =B28+1 | C29: =WEEKDAY(B29)+1 | F29: 0 | G29: 0 | H29: 0 | I29: 0 | L29: =IF(A29="U",(G29-F29)+(I29-H29)+(K29-J29),"NÃO ÚTIL") | M29: =IF(A29="U",L7,"NÃO ÚTIL") | N29: =IF(A29="U",(L29-M29),"NÃO ÚTIL") | P29: =IF(N29="não útil",0,N29) | Q29: =P29+Q28 | R29: =Q29+$Q$4 | S29: =IF(B29=T29,"HOJE",".") | T29: =TODAY() | U29: =IF(S29="HOJE",R29,0)
A30: =IF(OR(C30=2,C30=8),"F","U") | B30: =B29+1 | C30: =WEEKDAY(B30)+1 | F30: 0 | G30: 0 | H30: 0 | I30: 0 | L30: =IF(A30="U",(G30-F30)+(I30-H30)+(K30-J30),"NÃO ÚTIL") | M30: =IF(A30="U",L7,"NÃO ÚTIL") | N30: =IF(A30="U",(L30-M30),"NÃO ÚTIL") | P30: =IF(N30="não útil",0,N30) | Q30: =P30+Q29 | R30: =Q30+$Q$4 | S30: =IF(B30=T30,"HOJE",".") | T30: =TODAY() | U30: =IF(S30="HOJE",R30,0)
A31: =IF(OR(C31=2,C31=8),"F","U") | B31: =B30+1 | C31: =WEEKDAY(B31)+1 | F31: 0 | G31: 0 | H31: 0 | I31: 0 | L31: =IF(A31="U",(G31-F31)+(I31-H31)+(K31-J31),"NÃO ÚTIL") | M31: =IF(A31="U",L7,"NÃO ÚTIL") | N31: =IF(A31="U",(L31-M31),"NÃO ÚTIL") | P31: =IF(N31="não útil",0,N31) | Q31: =P31+Q30 | R31: =Q31+$Q$4 | S31: =IF(B31=T31,"HOJE",".") | T31: =TODAY() | U31: =IF(S31="HOJE",R31,0)
A32: =IF(OR(C32=2,C32=8),"F","U") | B32: =B31+1 | C32: =WEEKDAY(B32)+1 | F32: 0 | G32: 0 | H32: 0 | I32: 0 | L32: =IF(A32="U",(G32-F32)+(I32-H32)+(K32-J32),"NÃO ÚTIL") | M32: =IF(A32="U",L7,"NÃO ÚTIL") | N32: =IF(A32="U",(L32-M32),"NÃO ÚTIL") | P32: =IF(N32="não útil",0,N32) | Q32: =P32+Q31 | R32: =Q32+$Q$4 | S32: =IF(B32=T32,"HOJE",".") | T32: =TODAY() | U32: =IF(S32="HOJE",R32,0)
A33: =IF(OR(C33=2,C33=8),"F","U") | B33: =B32+1 | C33: =WEEKDAY(B33)+1 | F33: 0 | G33: 0 | H33: 0 | I33: 0 | L33: =IF(A33="U",(G33-F33)+(I33-H33)+(K33-J33),"NÃO ÚTIL") | M33: =IF(A33="U",L7,"NÃO ÚTIL") | N33: =IF(A33="U",(L33-M33),"NÃO ÚTIL") | P33: =IF(N33="não útil",0,N33) | Q33: =P33+Q32 | R33: =Q33+$Q$4 | S33: =IF(B33=T33,"HOJE",".") | T33: =TODAY() | U33: =IF(S33="HOJE",R33,0)
A34: =IF(OR(C34=2,C34=8),"F","U") | B34: =B33+1 | C34: =WEEKDAY(B34)+1 | F34: 0 | G34: 0 | H34: 0 | I34: 0 | L34: =IF(A34="U",(G34-F34)+(I34-H34)+(K34-J34),"NÃO ÚTIL") | M34: =IF(A34="U",L7,"NÃO ÚTIL") | N34: =IF(A34="U",(L34-M34),"NÃO ÚTIL") | P34: =IF(N34="não útil",0,N34) | Q34: =P34+Q33 | R34: =Q34+$Q$4 | S34: =IF(B34=T34,"HOJE",".") | T34: =TODAY() | U34: =IF(S34="HOJE",R34,0)
A35: =IF(OR(C35=2,C35=8),"F","U") | B35: =B34+1 | C35: =WEEKDAY(B35)+1 | F35: 0 | G35: 0 | H35: 0 | I35: 0 | L35: =IF(A35="U",(G35-F35)+(I35-H35)+(K35-J35),"NÃO ÚTIL") | M35: =IF(A35="U",L7,"NÃO ÚTIL") | N35: =IF(A35="U",(L35-M35),"NÃO ÚTIL") | P35: =IF(N35="não útil",0,N35) | Q35: =P35+Q34 | R35: =Q35+$Q$4 | S35: =IF(B35=T35,"HOJE",".") | T35: =TODAY() | U35: =IF(S35="HOJE",R35,0)
A36: =IF(OR(C36=2,C36=8),"F","U") | B36: =B35+1 | C36: =WEEKDAY(B36)+1 | F36: 0 | G36: 0 | H36: 0 | I36: 0 | L36: =IF(A36="U",(G36-F36)+(I36-H36)+(K36-J36),"NÃO ÚTIL") | M36: =IF(A36="U",L7,"NÃO ÚTIL") | N36: =IF(A36="U",(L36-M36),"NÃO ÚTIL") | P36: =IF(N36="não útil",0,N36) | Q36: =P36+Q35 | R36: =Q36+$Q$4 | S36: =IF(B36=T36,"HOJE",".") | T36: =TODAY() | U36: =IF(S36="HOJE",R36,0)
A37: =IF(OR(C37=2,C37=8),"F","U") | B37: =B36+1 | C37: =WEEKDAY(B37)+1 | F37: 0 | G37: 0 | H37: 0 | I37: 0 | L37: =IF(A37="U",(G37-F37)+(I37-H37)+(K37-J37),"NÃO ÚTIL") | M37: =IF(A37="U",L7,"NÃO ÚTIL") | N37: =IF(A37="U",(L37-M37),"NÃO ÚTIL") | P37: =IF(N37="não útil",0,N37) | Q37: =P37+Q36 | R37: =Q37+$Q$4 | S37: =IF(B37=T37,"HOJE",".") | T37: =TODAY() | U37: =IF(S37="HOJE",R37,0)
A38: =IF(OR(C38=2,C38=8),"F","U") | B38: =B37+1 | C38: =WEEKDAY(B38)+1 | F38: 0 | G38: 0 | H38: 0 | I38: 0 | L38: =IF(A38="U",(G38-F38)+(I38-H38)+(K38-J38),"NÃO ÚTIL") | M38: =IF(A38="U",L7,"NÃO ÚTIL") | N38: =IF(A38="U",(L38-M38),"NÃO ÚTIL") | P38: =IF(N38="não útil",0,N38) | Q38: =P38+Q37 | R38: =Q38+$Q$4 | S38: =IF(B38=T38,"HOJE",".") | T38: =TODAY() | U38: =IF(S38="HOJE",R38,0)
A39: =IF(OR(C39=2,C39=8),"F","U") | B39: =B38+1 | C39: =WEEKDAY(B39)+1 | F39: 0 | G39: 0 | H39: 0 | I39: 0 | L39: =IF(A39="U",(G39-F39)+(I39-H39)+(K39-J39),"NÃO ÚTIL") | M39: =IF(A39="U",L7,"NÃO ÚTIL") | N39: =IF(A39="U",(L39-M39),"NÃO ÚTIL") | P39: =IF(N39="não útil",0,N39) | Q39: =P39+Q38 | R39: =Q39+$Q$4 | S39: =IF(B39=T39,"HOJE",".") | T39: =TODAY() | U39: =IF(S39="HOJE",R39,0)
A40: =IF(OR(C40=2,C40=8),"F","U") | B40: =B39+1 | C40: =WEEKDAY(B40)+1 | F40: 0 | G40: 0 | H40: 0 | I40: 0 | L40: =IF(A40="U",(G40-F40)+(I40-H40)+(K40-J40),"NÃO ÚTIL") | M40: =IF(A40="U",L7,"NÃO ÚTIL") | N40: =IF(A40="U",(L40-M40),"NÃO ÚTIL") | P40: =IF(N40="não útil",0,N40) | Q40: =P40+Q39 | R40: =Q40+$Q$4 | S40: =IF(B40=T40,"HOJE",".") | T40: =TODAY() | U40: =IF(S40="HOJE",R40,0)
A41: =IF(OR(C41=2,C41=8),"F","U") | B41: =B40+1 | C41: =WEEKDAY(B41)+1 | F41: 0 | G41: 0 | H41: 0 | I41: 0 | L41: =IF(A41="U",(G41-F41)+(I41-H41)+(K41-J41),"NÃO ÚTIL") | M41: =IF(A41="U",L7,"NÃO ÚTIL") | N41: =IF(A41="U",(L41-M41),"NÃO ÚTIL") | P41: =IF(N41="não útil",0,N41) | Q41: =P41+Q40 | R41: =Q41+$Q$4 | S41: =IF(B41=T41,"HOJE",".") | T41: =TODAY() | U41: =IF(S41="HOJE",R41,0)
A42: U | B42: =B41+1 | C42: =WEEKDAY(B42)+1 | F42: 0 | G42: 0 | H42: 0 | I42: 0 | L42: =IF(A42="U",(G42-F42)+(I42-H42)+(K42-J42),"NÃO ÚTIL") | M42: =IF(A42="U",L7,"NÃO ÚTIL") | N42: =IF(A42="U",(L42-M42),"NÃO ÚTIL") | P42: =IF(N42="não útil",0,N42) | Q42: =P42+Q41 | R42: =Q42+$Q$4 | S42: =IF(B42=T42,"HOJE",".") | T42: =TODAY() | U42: =IF(S42="HOJE",R42,0)
...

Sheet ABR
A2: GOVERNO DO ESTADO DO ESPÍRITO SANTO
A3: SUPERINTENDÊNCIA REGIONAL DE EDUCAÇÃO DE CARAPINA
A4: CARTÃO DE PONTO | Q4: 0 | R4: saldo anterior
A6: NOME: | C6: =JAN!C6:N11 | J6: MÊS: | K6: 43555
A7: CARGO: | C7: =JAN!C7:I7 | J7: CH DIÁRIA: | L7: =JAN!L7 | M7: =JAN!M7 | N7: =JAN!N7
A8: FUNÇÃO: | C8: =JAN!C8:I8 | J8: DIAS ÚTEIS: | L8: =COUNTIF(A14:A43,"U")
A9: EMPRESA: | C9: =JAN!C9:I9 | J9: CNPJ: | K9: =JAN!K9:L9 | M9: EXERCÍCIO: | N9: 2021 | P9: U: DIA ÚTIL
A10: LOCALIZAÇÃO: | C10: =JAN!C10:I10 | J10: NÚMERO FUNCIONAL: | L10: =JAN!L10 | M10: VÍNCULO: | N10: =JAN!N10 | P10: F: SÁBADOS; DOMINGOS E FERIADOS
A11: REGIME JURÍDICO: | C11: =JAN!C11:E11 | F11: ÓRGÃO DE EXERCÍCIO: | I11: Secretaria de Estado da Educação
A12: DIAS DA SEMANA | F12: 1º TURNO | H12: 2º TURNO | J12: 3º TURNO | L12: HORAS TRABALHADAS | M12: CH PADRÃO | N12: SALDO | P12: saldo acumulado até hoje | R12: =SUM(U14:U44)+SUM(FEV!U44)+SUM(MAR!U14:U44)+SUM(ABR!U14:U44)+SUM(MAIO!U14:U44)+SUM(JUN!U14:U44)+SUM(JUL!U14:U44)+SUM(AGO!U14:U44)+SUM(SET!U14:U44)+SUM(OUT!U14:U44)+SUM(NOV!U14:U44)+SUM(DEZ!U14:U44) | U12: =TODAY()
F13: ENTRADA MANHÃ | G13: SAÍDA MANHÃ | H13: ENTRADA TARDE | I13: SAÍDA DA TARDE | J13: ENTRADA EXTRA | K13: SAÍDA EXTRA | L13: POR DIA | M13: DIÁRIA | N13: DIÁRIO
A14: =IF(OR(C14=2,C14=8),"F","U") | B14: =K6 | C14: =WEEKDAY(B14)+1 | F14: 0 | G14: 0 | H14: 0 | I14: 0 | L14: =IF(A14="U",(G14-F14)+(I14-H14)+(K14-J14),"NÃO ÚTIL") | M14: =IF(A14="U",L7,"NÃO ÚTIL") | N14: =IF(A14="U",(L14-M14),"NÃO ÚTIL") | P14: =IF(N14="não útil",0,N14) | Q14: =P14 | R14: =Q14+$Q$4 | S14: =IF(B14=T14,"HOJE",".") | T14: =TODAY() | U14: =IF(S14="HOJE",R14,0)
A15: =IF(OR(C15=2,C15=8),"F","U") | B15: =B14+1 | C15: =WEEKDAY(B15)+1 | F15: 0 | G15: 0 | H15: 0 | I15: 0 | L15: =IF(A15="U",(G15-F15)+(I15-H15)+(K15-J15),"NÃO ÚTIL") | M15: =IF(A15="U",L7,"NÃO ÚTIL") | N15: =IF(A15="U",(L15-M15),"NÃO ÚTIL") | P15: =IF(N15="não útil",0,N15) | Q15: =P15+Q14 | R15: =Q15+$Q$4 | S15: =IF(B15=T15,"HOJE",".") | T15: =TODAY() | U15: =IF(S15="HOJE",R15,0)
A16: =IF(OR(C16=2,C16=8),"F","U") | B16: =B15+1 | C16: =WEEKDAY(B16)+1 | F16: 0 | G16: 0 | H16: 0 | I16: 0 | L16: =IF(A16="U",(G16-F16)+(I16-H16)+(K16-J16),"NÃO ÚTIL") | M16: =IF(A16="U",L7,"NÃO ÚTIL") | N16: =IF(A16="U",(L16-M16),"NÃO ÚTIL") | P16: =IF(N16="não útil",0,N16) | Q16: =P16+Q15 | R16: =Q16+$Q$4 | S16: =IF(B16=T16,"HOJE",".") | T16: =TODAY() | U16: =IF(S16="HOJE",R16,0)
A17: U | B17: =B16+1 | C17: =WEEKDAY(B17)+1 | F17: 0 | G17: 0 | H17: 0 | I17: 0 | L17: =IF(A17="U",(G17-F17)+(I17-H17)+(K17-J17),"NÃO ÚTIL") | M17: =IF(A17="U",L7,"NÃO ÚTIL") | N17: =IF(A17="U",(L17-M17),"NÃO ÚTIL") | P17: =IF(N17="não útil",0,N17) | Q17: =P17+Q16 | R17: =Q17+$Q$4 | S17: =IF(B17=T17,"HOJE",".") | T17: =TODAY() | U17: =IF(S17="HOJE",R17,0)
A18: =IF(OR(C18=2,C18=8),"F","U") | B18: =B17+1 | C18: =WEEKDAY(B18)+1 | F18: 0 | G18: 0 | H18: 0 | I18: 0 | L18: =IF(A18="U",(G18-F18)+(I18-H18)+(K18-J18),"NÃO ÚTIL") | M18: =IF(A18="U",L7,"NÃO ÚTIL") | N18: =IF(A18="U",(L18-M18),"NÃO ÚTIL") | P18: =IF(N18="não útil",0,N18) | Q18: =P18+Q17 | R18: =Q18+$Q$4 | S18: =IF(B18=T18,"HOJE",".") | T18: =TODAY() | U18: =IF(S18="HOJE",R18,0)
A19: =IF(OR(C19=2,C19=8),"F","U") | B19: =B18+1 | C19: =WEEKDAY(B19)+1 | F19: 0 | G19: 0 | H19: 0 | I19: 0 | L19: =IF(A19="U",(G19-F19)+(I19-H19)+(K19-J19),"NÃO ÚTIL") | M19: =IF(A19="U",L7,"NÃO ÚTIL") | N19: =IF(A19="U",(L19-M19),"NÃO ÚTIL") | P19: =IF(N19="não útil",0,N19) | Q19: =P19+Q18 | R19: =Q19+$Q$4 | S19: =IF(B19=T19,"HOJE",".") | T19: =TODAY() | U19: =IF(S19="HOJE",R19,0)
A20: =IF(OR(C20=2,C20=8),"F","U") | B20: =B19+1 | C20: =WEEKDAY(B20)+1 | F20: 0 | G20: 0 | H20: 0 | I20: 0 | L20: =IF(A20="U",(G20-F20)+(I20-H20)+(K20-J20),"NÃO ÚTIL") | M20: =IF(A20="U",L7,"NÃO ÚTIL") | N20: =IF(A20="U",(L20-M20),"NÃO ÚTIL") | P20: =IF(N20="não útil",0,N20) | Q20: =P20+Q19 | R20: =Q20+$Q$4 | S20: =IF(B20=T20,"HOJE",".") | T20: =TODAY() | U20: =IF(S20="HOJE",R20,0)
A21: =IF(OR(C21=2,C21=8),"F","U") | B21: =B20+1 | C21: =WEEKDAY(B21)+1 | F21: 0 | G21: 0 | H21: 0 | I21: 0 | L21: =IF(A21="U",(G21-F21)+(I21-H21)+(K21-J21),"NÃO ÚTIL") | M21: =IF(A21="U",L7,"NÃO ÚTIL") | N21: =IF(A21="U",(L21-M21),"NÃO ÚTIL") | P21: =IF(N21="não útil",0,N21) | Q21: =P21+Q20 | R21: =Q21+$Q$4 | S21: =IF(B21=T21,"HOJE",".") | T21: =TODAY() | U21: =IF(S21="HOJE",R21,0)
A22: f | B22: =B21+1 | C22: =WEEKDAY(B22)+1 | F22: 0 | G22: 0 | H22: 0 | I22: 0 | L22: =IF(A22="U",(G22-F22)+(I22-H22)+(K22-J22),"NÃO ÚTIL") | M22: =IF(A22="U",L7,"NÃO ÚTIL") | N22: =IF(A22="U",(L22-M22),"NÃO ÚTIL") | P22: =IF(N22="não útil",0,N22) | Q22: =P22+Q21 | R22: =Q22+$Q$4 | S22: =IF(B22=T22,"HOJE",".") | T22: =TODAY() | U22: =IF(S22="HOJE",R22,0)
A23: =IF(OR(C23=2,C23=8),"F","U") | B23: =B22+1 | C23: =WEEKDAY(B23)+1 | F23: 0 | G23: 0 | H23: 0 | I23: 0 | L23: =IF(A23="U",(G23-F23)+(I23-H23)+(K23-J23),"NÃO ÚTIL") | M23: =IF(A23="U",L7,"NÃO ÚTIL") | N23: =IF(A23="U",(L23-M23),"NÃO ÚTIL") | P23: =IF(N23="não útil",0,N23) | Q23: =P23+Q22 | R23: =Q23+$Q$4 | S23: =IF(B23=T23,"HOJE",".") | T23: =TODAY() | U23: =IF(S23="HOJE",R23,0)
A24: =IF(OR(C24=2,C24=8),"F","U") | B24: =B23+1 | C24: =WEEKDAY(B24)+1 | F24: 0 | G24: 0 | H24: 0 | I24: 0 | L24: =IF(A24="U",(G24-F24)+(I24-H24)+(K24-J24),"NÃO ÚTIL") | M24: =IF(A24="U",L7,"NÃO ÚTIL") | N24: =IF(A24="U",(L24-M24),"NÃO ÚTIL") | P24: =IF(N24="não útil",0,N24) | Q24: =P24+Q23 | R24: =Q24+$Q$4 | S24: =IF(B24=T24,"HOJE",".") | T24: =TODAY() | U24: =IF(S24="HOJE",R24,0)
A25: =IF(OR(C25=2,C25=8),"F","U") | B25: =B24+1 | C25: =WEEKDAY(B25)+1 | F25: 0 | G25: 0 | H25: 0 | I25: 0 | L25: =IF(A25="U",(G25-F25)+(I25-H25)+(K25-J25),"NÃO ÚTIL") | M25: =IF(A25="U",L7,"NÃO ÚTIL") | N25: =IF(A25="U",(L25-M25),"NÃO ÚTIL") | P25: =IF(N25="não útil",0,N25) | Q25: =P25+Q24 | R25: =Q25+$Q$4 | S25: =IF(B25=T25,"HOJE",".") | T25: =TODAY() | U25: =IF(S25="HOJE",R25,0)
A26: =IF(OR(C26=2,C26=8),"F","U") | B26: =B25+1 | C26: =WEEKDAY(B26)+1 | F26: 0 | G26: 0 | H26: 0 | I26: 0 | L26: =IF(A26="U",(G26-F26)+(I26-H26)+(K26-J26),"NÃO ÚTIL") | M26: =IF(A26="U",L7,"NÃO ÚTIL") | N26: =IF(A26="U",(L26-M26),"NÃO ÚTIL") | P26: =IF(N26="não útil",0,N26) | Q26: =P26+Q25 | R26: =Q26+$Q$4 | S26: =IF(B26=T26,"HOJE",".") | T26: =TODAY() | U26: =IF(S26="HOJE",R26,0)
A27: =IF(OR(C27=2,C27=8),"F","U") | B27: =B26+1 | C27: =WEEKDAY(B27)+1 | F27: 0 | G27: 0 | H27: 0 | I27: 0 | L27: =IF(A27="U",(G27-F27)+(I27-H27)+(K27-J27),"NÃO ÚTIL") | M27: =IF(A27="U",L7,"NÃO ÚTIL") | N27: =IF(A27="U",(L27-M27),"NÃO ÚTIL") | P27: =IF(N27="não útil",0,N27) | Q27: =P27+Q26 | R27: =Q27+$Q$4 | S27: =IF(B27=T27,"HOJE",".") | T27: =TODAY() | U27: =IF(S27="HOJE",R27,0)
A28: =IF(OR(C28=2,C28=8),"F","U") | B28: =B27+1 | C28: =WEEKDAY(B28)+1 | F28: 0 | G28: 0 | H28: 0 | I28: 0 | L28: =IF(A28="U",(G28-F28)+(I28-H28)+(K28-J28),"NÃO ÚTIL") | M28: =IF(A28="U",L7,"NÃO ÚTIL") | N28: =IF(A28="U",(L28-M28),"NÃO ÚTIL") | P28: =IF(N28="não útil",0,N28) | Q28: =P28+Q27 | R28: =Q28+$Q$4 | S28: =IF(B28=T28,"HOJE",".") | T28: =TODAY() | U28: =IF(S28="HOJE",R28,0)
A29: =IF(OR(C29=2,C29=8),"F","U") | B29: =B28+1 | C29: =WEEKDAY(B29)+1 | F29: 0 | G29: 0 | H29: 0 | I29: 0 | L29: =IF(A29="U",(G29-F29)+(I29-H29)+(K29-J29),"NÃO ÚTIL") | M29: =IF(A29="U",L7,"NÃO ÚTIL") | N29: =IF(A29="U",(L29-M29),"NÃO ÚTIL") | P29: =IF(N29="não útil",0,N29) | Q29: =P29+Q28 | R29: =Q29+$Q$4 | S29: =IF(B29=T29,"HOJE",".") | T29: =TODAY() | U29: =IF(S29="HOJE",R29,0)
A30: =IF(OR(C30=2,C30=8),"F","U") | B30: =B29+1 | C30: =WEEKDAY(B30)+1 | F30: 0 | G30: 0 | H30: 0 | I30: 0 | L30: =IF(A30="U",(G30-F30)+(I30-H30)+(K30-J30),"NÃO ÚTIL") | M30: =IF(A30="U",L7,"NÃO ÚTIL") | N30: =IF(A30="U",(L30-M30),"NÃO ÚTIL") | P30: =IF(N30="não útil",0,N30) | Q30: =P30+Q29 | R30: =Q30+$Q$4 | S30: =IF(B30=T30,"HOJE",".") | T30: =TODAY() | U30: =IF(S30="HOJE",R30,0)
A31: =IF(OR(C31=2,C31=8),"F","U") | B31: =B30+1 | C31: =WEEKDAY(B31)+1 | F31: 0 | G31: 0 | H31: 0 | I31: 0 | L31: =IF(A31="U",(G31-F31)+(I31-H31)+(K31-J31),"NÃO ÚTIL") | M31: =IF(A31="U",L7,"NÃO ÚTIL") | N31: =IF(A31="U",(L31-M31),"NÃO ÚTIL") | P31: =IF(N31="não útil",0,N31) | Q31: =P31+Q30 | R31: =Q31+$Q$4 | S31: =IF(B31=T31,"HOJE",".") | T31: =TODAY() | U31: =IF(S31="HOJE",R31,0)
A32: =IF(OR(C32=2,C32=8),"F","U") | B32: =B31+1 | C32: =WEEKDAY(B32)+1 | F32: 0 | G32: 0 | H32: 0 | I32: 0 | L32: =IF(A32="U",(G32-F32)+(I32-H32)+(K32-J32),"NÃO ÚTIL") | M32: =IF(A32="U",L7,"NÃO ÚTIL") | N32: =IF(A32="U",(L32-M32),"NÃO ÚTIL") | P32: =IF(N32="não útil",0,N32) | Q32: =P32+Q31 | R32: =Q32+$Q$4 | S32: =IF(B32=T32,"HOJE",".") | T32: =TODAY() | U32: =IF(S32="HOJE",R32,0)
A33: =IF(OR(C33=2,C33=8),"F","U") | B33: =B32+1 | C33: =WEEKDAY(B33)+1 | F33: 0 | G33: 0 | H33: 0 | I33: 0 | L33: =IF(A33="U",(G33-F33)+(I33-H33)+(K33-J33),"NÃO ÚTIL") | M33: =IF(A33="U",L7,"NÃO ÚTIL") | N33: =IF(A33="U",(L33-M33),"NÃO ÚTIL") | P33: =IF(N33="não útil",0,N33) | Q33: =P33+Q32 | R33: =Q33+$Q$4 | S33: =IF(B33=T33,"HOJE",".") | T33: =TODAY() | U33: =IF(S33="HOJE",R33,0)
A34: =IF(OR(C34=2,C34=8),"F","U") | B34: =B33+1 | C34: =WEEKDAY(B34)+1 | F34: 0 | G34: 0 | H34: 0 | I34: 0 | L34: =IF(A34="U",(G34-F34)+(I34-H34)+(K34-J34),"NÃO ÚTIL") | M34: =IF(A34="U",L7,"NÃO ÚTIL") | N34: =IF(A34="U",(L34-M34),"NÃO ÚTIL") | P34: =IF(N34="não útil",0,N34) | Q34: =P34+Q33 | R34: =Q34+$Q$4 | S34: =IF(B34=T34,"HOJE",".") | T34: =TODAY() | U34: =IF(S34="HOJE",R34,0)
A35: =IF(OR(C35=2,C35=8),"F","U") | B35: =B34+1 | C35: =WEEKDAY(B35)+1 | F35: 0 | G35: 0 | H35: 0 | I35: 0 | L35: =IF(A35="U",(G35-F35)+(I35-H35)+(K35-J35),"NÃO ÚTIL") | M35: =IF(A35="U",L7,"NÃO ÚTIL") | N35: =IF(A35="U",(L35-M35),"NÃO ÚTIL") | P35: =IF(N35="não útil",0,N35) | Q35: =P35+Q34 | R35: =Q35+$Q$4 | S35: =IF(B35=T35,"HOJE",".") | T35: =TODAY() | U35: =IF(S35="HOJE",R35,0)
A36: =IF(OR(C36=2,C36=8),"F","U") | B36: =B35+1 | C36: =WEEKDAY(B36)+1 | F36: 0 | G36: 0 | H36: 0 | I36: 0 | L36: =IF(A36="U",(G36-F36)+(I36-H36)+(K36-J36),"NÃO ÚTIL") | M36: =IF(A36="U",L7,"NÃO ÚTIL") | N36: =IF(A36="U",(L36-M36),"NÃO ÚTIL") | P36: =IF(N36="não útil",0,N36) | Q36: =P36+Q35 | R36: =Q36+$Q$4 | S36: =IF(B36=T36,"HOJE",".") | T36: =TODAY() | U36: =IF(S36="HOJE",R36,0)
A37: =IF(OR(C37=2,C37=8),"F","U") | B37: =B36+1 | C37: =WEEKDAY(B37)+1 | F37: 0 | G37: 0 | H37: 0 | I37: 0 | L37: =IF(A37="U",(G37-F37)+(I37-H37)+(K37-J37),"NÃO ÚTIL") | M37: =IF(A37="U",L7,"NÃO ÚTIL") | N37: =IF(A37="U",(L37-M37),"NÃO ÚTIL") | P37: =IF(N37="não útil",0,N37) | Q37: =P37+Q36 | R37: =Q37+$Q$4 | S37: =IF(B37=T37,"HOJE",".") | T37: =TODAY() | U37: =IF(S37="HOJE",R37,0)
A38: =IF(OR(C38=2,C38=8),"F","U") | B38: =B37+1 | C38: =WEEKDAY(B38)+1 | F38: 0 | G38: 0 | H38: 0 | I38: 0 | L38: =IF(A38="U",(G38-F38)+(I38-H38)+(K38-J38),"NÃO ÚTIL") | M38: =IF(A38="U",L7,"NÃO ÚTIL") | N38: =IF(A38="U",(L38-M38),"NÃO ÚTIL") | P38: =IF(N38="não útil",0,N38) | Q38: =P38+Q37 | R38: =Q38+$Q$4 | S38: =IF(B38=T38,"HOJE",".") | T38: =TODAY() | U38: =IF(S38="HOJE",R38,0)
A39: =IF(OR(C39=2,C39=8),"F","U") | B39: =B38+1 | C39: =WEEKDAY(B39)+1 | F39: 0 | G39: 0 | H39: 0 | I39: 0 | L39: =IF(A39="U",(G39-F39)+(I39-H39)+(K39-J39),"NÃO ÚTIL") | M39: =IF(A39="U",L7,"NÃO ÚTIL") | N39: =IF(A39="U",(L39-M39),"NÃO ÚTIL") | P39: =IF(N39="não útil",0,N39) | Q39: =P39+Q38 | R39: =Q39+$Q$4 | S39: =IF(B39=T39,"HOJE",".") | T39: =TODAY() | U39: =IF(S39="HOJE",R39,0)
A40: =IF(OR(C40=2,C40=8),"F","U") | B40: =B39+1 | C40: =WEEKDAY(B40)+1 | F40: 0 | G40: 0 | H40: 0 | I40: 0 | L40: =IF(A40="U",(G40-F40)+(I40-H40)+(K40-J40),"NÃO ÚTIL") | M40: =IF(A40="U",L7,"NÃO ÚTIL") | N40: =IF(A40="U",(L40-M40),"NÃO ÚTIL") | P40: =IF(N40="não útil",0,N40) | Q40: =P40+Q39 | R40: =Q40+$Q$4 | S40: =IF(B40=T40,"HOJE",".") | T40: =TODAY() | U40: =IF(S40="HOJE",R40,0)
A41: =IF(OR(C41=2,C41=8),"F","U") | B41: =B40+1 | C41: =WEEKDAY(B41)+1 | F41: 0 | G41: 0 | H41: 0 | I41: 0 | L41: =IF(A41="U",(G41-F41)+(I41-H41),"NÃO ÚTIL") | M41: =IF(A41="U",L7,"NÃO ÚTIL") | N41: =IF(A41="U",(L41-M41),"NÃO ÚTIL") | P41: =IF(N41="não útil",0,N41) | Q41: =P41+Q40 | R41: =Q41+$Q$4 | S41: =IF(B41=T41,"HOJE",".") | T41: =TODAY() | U41: =IF(S41="HOJE",R41,0)
A42: =IF(OR(C42=2,C42=8),"F","U") | B42: =B41+1 | C42: =WEEKDAY(B42)+1 | F42: 0 | G42: 0 | H42: 0 | I42: 0 | L42: =IF(A42="U",(G42-F42)+(I42-H42)+(K42-J42),"NÃO ÚTIL") | M42: =IF(A42="U",L7,"NÃO ÚTIL") | N42: =IF(A42="U",(L42-M42),"NÃO ÚTIL") | P42: =IF(N42="não útil",0,N42) | Q42: =P42+Q41 | R42: =Q42+$Q$4 | S42: =IF(B42=T42,"HOJE",".") | T42: =TODAY() | U42: =IF(S42="HOJE",R42,0)
...

Sheet MAIO
A2: GOVERNO DO ESTADO DO ESPÍRITO SANTO
A3: SUPERINTENDÊNCIA REGIONAL DE EDUCAÇÃO DE CARAPINA
A4: CARTÃO DE PONTO | Q4: 0 | R4: saldo anterior
A6: NOME: | C6: =JAN!C6:I6 | J6: MÊS: | K6: 43585
A7: CARGO: | C7: =JAN!C7:I7 | J7: CH DIÁRIA: | L7: =JAN!L7 | M7: =JAN!M7 | N7: =JAN!N7
A8: FUNÇÃO: | C8: =JAN!C8:I8 | J8: DIAS ÚTEIS: | L8: =COUNTIF(A14:A43,"U")
A9: EMPRESA: | C9: =JAN!C9:I9 | J9: CNPJ: | K9: =JAN!K9:L9 | M9: EXERCÍCIO: | N9: 2021 | P9: U: DIA ÚTIL
A10: LOCALIZAÇÃO: | C10: =JAN!C10:I10 | J10: NÚMERO FUNCIONAL: | L10: =JAN!L10 | M10: VÍNCULO: | N10: =JAN!N10 | P10: F: SÁBADOS; DOMINGOS E FERIADOS
A11: REGIME JURÍDICO: | C11: =JAN!C11:E11 | F11: ÓRGÃO DE EXERCÍCIO: | I11: Secretaria de Estado da Educação
A12: DIAS DA SEMANA | F12: 1º TURNO | H12: 2º TURNO | J12: 3º TURNO | L12: HORAS TRABALHADAS | M12: CH PADRÃO | N12: SALDO | P12: saldo acumulado até hoje | R12: =SUM(U14:U44)+SUM(FEV!U44)+SUM(MAR!U14:U44)+SUM(ABR!U14:U44)+SUM(MAIO!U14:U44)+SUM(JUN!U14:U44)+SUM(JUL!U14:U44)+SUM(AGO!U14:U44)+SUM(SET!U14:U44)+SUM(OUT!U14:U44)+SUM(NOV!U14:U44)+SUM(DEZ!U14:U44) | U12: =TODAY()
F13: ENTRADA MANHÃ | G13: SAÍDA MANHÃ | H13: ENTRADA TARDE | I13: SAÍDA DA TARDE | J13: ENTRADA EXTRA | K13: SAÍDA EXTRA | L13: POR DIA | M13: DIÁRIA | N13: DIÁRIO
A14: F | B14: =K6 | C14: =WEEKDAY(B14)+1 | F14: 0 | G14: 0 | H14: 0 | I14: 0 | L14: =IF(A14="U",(G14-F14)+(I14-H14)+(K14-J14),"NÃO ÚTIL") | M14: =IF(A14="U",L7,"NÃO ÚTIL") | N14: =IF(A14="U",(L14-M14),"NÃO ÚTIL") | P14: =IF(N14="não útil",0,N14) | Q14: =P14 | R14: =Q14+$Q$4 | S14: =IF(B14=T14,"HOJE",".") | T14: =TODAY() | U14: =IF(S14="HOJE",R14,0)
A15: F | B15: =B14+1 | C15: =WEEKDAY(B15)+1 | F15: 0 | G15: 0 | H15: 0 | I15: 0 | L15: =IF(A15="U",(G15-F15)+(I15-H15)+(K15-J15),"NÃO ÚTIL") | M15: =IF(A15="U",L7,"NÃO ÚTIL") | N15: =IF(A15="U",(L15-M15),"NÃO ÚTIL") | P15: =IF(N15="não útil",0,N15) | Q15: =P15+Q14 | R15: =Q15+$Q$4 | S15: =IF(B15=T15,"HOJE",".") | T15: =TODAY() | U15: =IF(S15="HOJE",R15,0)
A16: F | B16: =B15+1 | C16: =WEEKDAY(B16)+1 | F16: 0 | G16: 0 | H16: 0 | I16: 0 | L16: =IF(A16="U",(G16-F16)+(I16-H16)+(K16-J16),"NÃO ÚTIL") | M16: =IF(A16="U",L7,"NÃO ÚTIL") | N16: =IF(A16="U",(L16-M16),"NÃO ÚTIL") | P16: =IF(N16="não útil",0,N16) | Q16: =P16+Q15 | R16: =Q16+$Q$4 | S16: =IF(B16=T16,"HOJE",".") | T16: =TODAY() | U16: =IF(S16="HOJE",R16,0)
A17: =IF(OR(C17=2,C17=8),"F","U") | B17: =B16+1 | C17: =WEEKDAY(B17)+1 | F17: 0 | G17: 0 | H17: 0 | I17: 0 | L17: =IF(A17="U",(G17-F17)+(I17-H17)+(K17-J17),"NÃO ÚTIL") | M17: =IF(A17="U",L7,"NÃO ÚTIL") | N17: =IF(A17="U",(L17-M17),"NÃO ÚTIL") | P17: =IF(N17="não útil",0,N17) | Q17: =P17+Q16 | R17: =Q17+$Q$4 | S17: =IF(B17=T17,"HOJE",".") | T17: =TODAY() | U17: =IF(S17="HOJE",R17,0)
A18: =IF(OR(C18=2,C18=8),"F","U") | B18: =B17+1 | C18: =WEEKDAY(B18)+1 | F18: 0 | G18: 0 | H18: 0 | I18: 0 | L18: =IF(A18="U",(G18-F18)+(I18-H18)+(K18-J18),"NÃO ÚTIL") | M18: =IF(A18="U",L7,"NÃO ÚTIL") | N18: =IF(A18="U",(L18-M18),"NÃO ÚTIL") | P18: =IF(N18="não útil",0,N18) | Q18: =P18+Q17 | R18: =Q18+$Q$4 | S18: =IF(B18=T18,"HOJE",".") | T18: =TODAY() | U18: =IF(S18="HOJE",R18,0)
A19: =IF(OR(C19=2,C19=8),"F","U") | B19: =B18+1 | C19: =WEEKDAY(B19)+1 | F19: 0 | G19: 0 | H19: 0 | I19: 0 | L19: =IF(A19="U",(G19-F19)+(I19-H19)+(K19-J19),"NÃO ÚTIL") | M19: =IF(A19="U",L7,"NÃO ÚTIL") | N19: =IF(A19="U",(L19-M19),"NÃO ÚTIL") | P19: =IF(N19="não útil",0,N19) | Q19: =P19+Q18 | R19: =Q19+$Q$4 | S19: =IF(B19=T19,"HOJE",".") | T19: =TODAY() | U19: =IF(S19="HOJE",R19,0)
A20: =IF(OR(C20=2,C20=8),"F","U") | B20: =B19+1 | C20: =WEEKDAY(B20)+1 | F20: 0 | G20: 0 | H20: 0 | I20: 0 | L20: =IF(A20="U",(G20-F20)+(I20-H20)+(K20-J20),"NÃO ÚTIL") | M20: =IF(A20="U",L7,"NÃO ÚTIL") | N20: =IF(A20="U",(L20-M20),"NÃO ÚTIL") | P20: =IF(N20="não útil",0,N20) | Q20: =P20+Q19 | R20: =Q20+$Q$4 | S20: =IF(B20=T20,"HOJE",".") | T20: =TODAY() | U20: =IF(S20="HOJE",R20,0)
A21: =IF(OR(C21=2,C21=8),"F","U") | B21: =B20+1 | C21: =WEEKDAY(B21)+1 | F21: 0 | G21: 0 | H21: 0 | I21: 0 | L21: =IF(A21="U",(G21-F21)+(I21-H21)+(K21-J21),"NÃO ÚTIL") | M21: =IF(A21="U",L7,"NÃO ÚTIL") | N21: =IF(A21="U",(L21-M21),"NÃO ÚTIL") | P21: =IF(N21="não útil",0,N21) | Q21: =P21+Q20 | R21: =Q21+$Q$4 | S21: =IF(B21=T21,"HOJE",".") | T21: =TODAY() | U21: =IF(S21="HOJE",R21,0)
A22: =IF(OR(C22=2,C22=8),"F","U") | B22: =B21+1 | C22: =WEEKDAY(B22)+1 | F22: 0 | G22: 0 | H22: 0 | I22: 0 | L22: =IF(A22="U",(G22-F22)+(I22-H22)+(K22-J22),"NÃO ÚTIL") | M22: =IF(A22="U",L7,"NÃO ÚTIL") | N22: =IF(A22="U",(L22-M22),"NÃO ÚTIL") | P22: =IF(N22="não útil",0,N22) | Q22: =P22+Q21 | R22: =Q22+$Q$4 | S22: =IF(B22=T22,"HOJE",".") | T22: =TODAY() | U22: =IF(S22="HOJE",R22,0)
A23: =IF(OR(C23=2,C23=8),"F","U") | B23: =B22+1 | C23: =WEEKDAY(B23)+1 | F23: 0 | G23: 0 | H23: 0 | I23: 0 | L23: =IF(A23="U",(G23-F23)+(I23-H23)+(K23-J23),"NÃO ÚTIL") | M23: =IF(A23="U",L7,"NÃO ÚTIL") | N23: =IF(A23="U",(L23-M23),"NÃO ÚTIL") | P23: =IF(N23="não útil",0,N23) | Q23: =P23+Q22 | R23: =Q23+$Q$4 | S23: =IF(B23=T23,"HOJE",".") | T23: =TODAY() | U23: =IF(S23="HOJE",R23,0)
A24: =IF(OR(C24=2,C24=8),"F","U") | B24: =B23+1 | C24: =WEEKDAY(B24)+1 | F24: 0 | G24: 0 | H24: 0 | I24: 0 | L24: =IF(A24="U",(G24-F24)+(I24-H24)+(K24-J24),"NÃO ÚTIL") | M24: =IF(A24="U",L7,"NÃO ÚTIL") | N24: =IF(A24="U",(L24-M24),"NÃO ÚTIL") | P24: =IF(N24="não útil",0,N24) | Q24: =P24+Q23 | R24: =Q24+$Q$4 | S24: =IF(B24=T24,"HOJE",".") | T24: =TODAY() | U24: =IF(S24="HOJE",R24,0)
A25: =IF(OR(C25=2,C25=8),"F","U") | B25: =B24+1 | C25: =WEEKDAY(B25)+1 | F25: 0 | G25: 0 | H25: 0 | I25: 0 | L25: =IF(A25="U",(G25-F25)+(I25-H25)+(K25-J25),"NÃO ÚTIL") | M25: =IF(A25="U",L7,"NÃO ÚTIL") | N25: =IF(A25="U",(L25-M25),"NÃO ÚTIL") | P25: =IF(N25="não útil",0,N25) | Q25: =P25+Q24 | R25: =Q25+$Q$4 | S25: =IF(B25=T25,"HOJE",".") | T25: =TODAY() | U25: =IF(S25="HOJE",R25,0)
A26: =IF(OR(C26=2,C26=8),"F","U") | B26: =B25+1 | C26: =WEEKDAY(B26)+1 | F26: 0 | G26: 0 | H26: 0 | I26: 0 | L26: =IF(A26="U",(G26-F26)+(I26-H26)+(K26-J26),"NÃO ÚTIL") | M26: =IF(A26="U",L7,"NÃO ÚTIL") | N26: =IF(A26="U",(L26-M26),"NÃO ÚTIL") | P26: =IF(N26="não útil",0,N26) | Q26: =P26+Q25 | R26: =Q26+$Q$4 | S26: =IF(B26=T26,"HOJE",".") | T26: =TODAY() | U26: =IF(S26="HOJE",R26,0)
A27: =IF(OR(C27=2,C27=8),"F","U") | B27: =B26+1 | C27: =WEEKDAY(B27)+1 | F27: 0 | G27: 0 | H27: 0 | I27: 0 | L27: =IF(A27="U",(G27-F27)+(I27-H27)+(K27-J27),"NÃO ÚTIL") | M27: =IF(A27="U",L7,"NÃO ÚTIL") | N27: =IF(A27="U",(L27-M27),"NÃO ÚTIL") | P27: =IF(N27="não útil",0,N27) | Q27: =P27+Q26 | R27: =Q27+$Q$4 | S27: =IF(B27=T27,"HOJE",".") | T27: =TODAY() | U27: =IF(S27="HOJE",R27,0)
A28: =IF(OR(C28=2,C28=8),"F","U") | B28: =B27+1 | C28: =WEEKDAY(B28)+1 | F28: 0 | G28: 0 | H28: 0 | I28: 0 | L28: =IF(A28="U",(G28-F28)+(I28-H28)+(K28-J28),"NÃO ÚTIL") | M28: =IF(A28="U",L7,"NÃO ÚTIL") | N28: =IF(A28="U",(L28-M28),"NÃO ÚTIL") | P28: =IF(N28="não útil",0,N28) | Q28: =P28+Q27 | R28: =Q28+$Q$4 | S28: =IF(B28=T28,"HOJE",".") | T28: =TODAY() | U28: =IF(S28="HOJE",R28,0)
A29: =IF(OR(C29=2,C29=8),"F","U") | B29: =B28+1 | C29: =WEEKDAY(B29)+1 | F29: 0 | G29: 0 | H29: 0 | I29: 0 | L29: =IF(A29="U",(G29-F29)+(I29-H29)+(K29-J29),"NÃO ÚTIL") | M29: =IF(A29="U",L7,"NÃO ÚTIL") | N29: =IF(A29="U",(L29-M29),"NÃO ÚTIL") | P29: =IF(N29="não útil",0,N29) | Q29: =P29+Q28 | R29: =Q29+$Q$4 | S29: =IF(B29=T29,"HOJE",".") | T29: =TODAY() | U29: =IF(S29="HOJE",R29,0)
A30: =IF(OR(C30=2,C30=8),"F","U") | B30: =B29+1 | C30: =WEEKDAY(B30)+1 | F30: 0 | G30: 0 | H30: 0 | I30: 0 | L30: =IF(A30="U",(G30-F30)+(I30-H30)+(K30-J30),"NÃO ÚTIL") | M30: =IF(A30="U",L7,"NÃO ÚTIL") | N30: =IF(A30="U",(L30-M30),"NÃO ÚTIL") | P30: =IF(N30="não útil",0,N30) | Q30: =P30+Q29 | R30: =Q30+$Q$4 | S30: =IF(B30=T30,"HOJE",".") | T30: =TODAY() | U30: =IF(S30="HOJE",R30,0)
A31: =IF(OR(C31=2,C31=8),"F","U") | B31: =B30+1 | C31: =WEEKDAY(B31)+1 | F31: 0 | G31: 0 | H31: 0 | I31: 0 | L31: =IF(A31="U",(G31-F31)+(I31-H31)+(K31-J31),"NÃO ÚTIL") | M31: =IF(A31="U",L7,"NÃO ÚTIL") | N31: =IF(A31="U",(L31-M31),"NÃO ÚTIL") | P31: =IF(N31="não útil",0,N31) | Q31: =P31+Q30 | R31: =Q31+$Q$4 | S31: =IF(B31=T31,"HOJE",".") | T31: =TODAY() | U31: =IF(S31="HOJE",R31,0)
A32: =IF(OR(C32=2,C32=8),"F","U") | B32: =B31+1 | C32: =WEEKDAY(B32)+1 | F32: 0 | G32: 0 | H32: 0 | I32: 0 | L32: =IF(A32="U",(G32-F32)+(I32-H32)+(K32-J32),"NÃO ÚTIL") | M32: =IF(A32="U",L7,"NÃO ÚTIL") | N32: =IF(A32="U",(L32-M32),"NÃO ÚTIL") | P32: =IF(N32="não útil",0,N32) | Q32: =P32+Q31 | R32: =Q32+$Q$4 | S32: =IF(B32=T32,"HOJE",".") | T32: =TODAY() | U32: =IF(S32="HOJE",R32,0)
A33: =IF(OR(C33=2,C33=8),"F","U") | B33: =B32+1 | C33: =WEEKDAY(B33)+1 | F33: 0 | G33: 0 | H33: 0 | I33: 0 | L33: =IF(A33="U",(G33-F33)+(I33-H33)+(K33-J33),"NÃO ÚTIL") | M33: =IF(A33="U",L7,"NÃO ÚTIL") | N33: =IF(A33="U",(L33-M33),"NÃO ÚTIL") | P33: =IF(N33="não útil",0,N33) | Q33: =P33+Q32 | R33: =Q33+$Q$4 | S33: =IF(B33=T33,"HOJE",".") | T33: =TODAY() | U33: =IF(S33="HOJE",R33,0)
A34: =IF(OR(C34=2,C34=8),"F","U") | B34: =B33+1 | C34: =WEEKDAY(B34)+1 | F34: 0 | G34: 0 | H34: 0 | I34: 0 | L34: =IF(A34="U",(G34-F34)+(I34-H34)+(K34-J34),"NÃO ÚTIL") | M34: =IF(A34="U",L7,"NÃO ÚTIL") | N34: =IF(A34="U",(L34-M34),"NÃO ÚTIL") | P34: =IF(N34="não útil",0,N34) | Q34: =P34+Q33 | R34: =Q34+$Q$4 | S34: =IF(B34=T34,"HOJE",".") | T34: =TODAY() | U34: =IF(S34="HOJE",R34,0)
A35: =IF(OR(C35=2,C35=8),"F","U") | B35: =B34+1 | C35: =WEEKDAY(B35)+1 | F35: 0 | G35: 0 | H35: 0 | I35: 0 | L35: =IF(A35="U",(G35-F35)+(I35-H35)+(K35-J35),"NÃO ÚTIL") | M35: =IF(A35="U",L7,"NÃO ÚTIL") | N35: =IF(A35="U",(L35-M35),"NÃO ÚTIL") | P35: =IF(N35="não útil",0,N35) | Q35: =P35+Q34 | R35: =Q35+$Q$4 | S35: =IF(B35=T35,"HOJE",".") | T35: =TODAY() | U35: =IF(S35="HOJE",R35,0)
A36: F | B36: =B35+1 | C36: =WEEKDAY(B36)+1 | F36: 0 | G36: 0 | H36: 0 | I36: 0 | L36: =IF(A36="U",(G36-F36)+(I36-H36)+(K36-J36),"NÃO ÚTIL") | M36: =IF(A36="U",L7,"NÃO ÚTIL") | N36: =IF(A36="U",(L36-M36),"NÃO ÚTIL") | P36: =IF(N36="não útil",0,N36) | Q36: =P36+Q35 | R36: =Q36+$Q$4 | S36: =IF(B36=T36,"HOJE",".") | T36: =TODAY() | U36: =IF(S36="HOJE",R36,0)
A37: =IF(OR(C37=2,C37=8),"F","U") | B37: =B36+1 | C37: =WEEKDAY(B37)+1 | F37: 0 | G37: 0 | H37: 0 | I37: 0 | L37: =IF(A37="U",(G37-F37)+(I37-H37)+(K37-J37),"NÃO ÚTIL") | M37: =IF(A37="U",L7,"NÃO ÚTIL") | N37: =IF(A37="U",(L37-M37),"NÃO ÚTIL") | P37: =IF(N37="não útil",0,N37) | Q37: =P37+Q36 | R37: =Q37+$Q$4 | S37: =IF(B37=T37,"HOJE",".") | T37: =TODAY() | U37: =IF(S37="HOJE",R37,0)
